Workbook

Sheet Def_ocu_filtrada_2010_2019_2021
A2: age | B2: ocu | C2: reg | D2: Total | E2: Hombre | F2: Mujer | G2: No especificado
A3: Total | B3: Total | C3: 1990 | D3: 2417 | E3: 1425 | F3: 989 | G3: 3
A4: Total | B4: Total | C4: 1991 | D4: 2325 | E4: 1330 | F4: 992 | G4: 3
A5: Total | B5: Total | C5: 1992 | D5: 2359 | E5: 1390 | F5: 967 | G5: 2
A6: Total | B6: Total | C6: 1993 | D6: 2251 | E6: 1294 | F6: 955 | G6: 2
A7: Total | B7: Total | C7: 1994 | D7: 2272 | E7: 1329 | F7: 942 | G7: 1
A8: Total | B8: Total | C8: 1995 | D8: 2338 | E8: 1315 | F8: 1022 | G8: 1
A9: Total | B9: Total | C9: 1996 | D9: 2295 | E9: 1308 | F9: 986 | G9: 1
A10: Total | B10: Total | C10: 1997 | D10: 2403 | E10: 1366 | F10: 1035 | G10: 2
A11: Total | B11: Total | C11: 1998 | D11: 2370 | E11: 1317 | F11: 1051 | G11: 2
A12: Total | B12: Total | C12: 1999 | D12: 2351 | E12: 1342 | F12: 1008 | G12: 1
A13: Total | B13: Total | C13: 2000 | D13: 2412 | E13: 1381 | F13: 1031
A14: Total | B14: Total | C14: 2001 | D14: 2449 | E14: 1364 | F14: 1083 | G14: 2
A15: Total | B15: Total | C15: 2002 | D15: 2512 | E15: 1459 | F15: 1052 | G15: 1
A16: Total | B16: Total | C16: 2003 | D16: 2442 | E16: 1351 | F16: 1090 | G16: 1
A17: Total | B17: Total | C17: 2004 | D17: 2594 | E17: 1418 | F17: 1175 | G17: 1
A18: Total | B18: Total | C18: 2005 | D18: 2759 | E18: 1579 | F18: 1180
A19: Total | B19: Total | C19: 2006 | D19: 2831 | E19: 1630 | F19: 1200 | G19: 1
A20: Total | B20: Total | C20: 2007 | D20: 2866 | E20: 1679 | F20: 1186 | G20: 1
A21: Total | B21: Total | C21: 2008 | D21: 3052 | E21: 1723 | F21: 1328 | G21: 1
A22: Total | B22: Total | C22: 2009 | D22: 3107 | E22: 1812 | F22: 1295
A23: Total | B23: Total | C23: 2010 | D23: 3223 | E23: 1888 | F23: 1334 | G23: 1
A24: Total | B24: Total | C24: 2011 | D24: 3514 | E24: 2051 | F24: 1461 | G24: 2
A25: Total | B25: Total | C25: 2012 | D25: 3717 | E25: 2190 | F25: 1525 | G25: 2
A26: Total | B26: Total | C26: 2013 | D26: 3790 | E26: 2248 | F26: 1541 | G26: 1
A27: Total | B27: Total | C27: 2014 | D27: 3790 | E27: 2230 | F27: 1558 | G27: 2
A28: Total | B28: Total | C28: 2015 | D28: 4408 | E28: 2599 | F28: 1805 | G28: 4
A29: Total | B29: Total | C29: 2016 | D29: 4486 | E29: 2785 | F29: 1694 | G29: 7
A30: Total | B30: Total | C30: 2017 | D30: 4593 | E30: 2865 | F30: 1728
A31: Total | B31: Total | C31: 2018 | D31: 4533 | E31: 2793 | F31: 1740
A32: Total | B32: Total | C32: 2019 | D32: 4566 | E32: 2774 | F32: 1792
A33: Total | B33: Total | C33: 2020 | D33: 6057 | E33: 3694 | F33: 2363
A34: Total | B34: Total | C34: 2021 | D34: 7121 | E34: 4271 | F34: 2849 | G34: 1
A35: Total | B35: Total | C35: 2022 | D35: 5683 | E35: 3475 | F35: 2206 | G35: 2
A36: Total | B36: Total | C36: 2023 | D36: 5594 | E36: 3355 | F36: 2239
A37: Total | B37: Total | C37: 2024 | D37: 5610 | E37: 3412 | F37: 2198
A38: Total | B38: 1900 | C38: 1998 | D38: 3 | E38: 3
A39: Total | B39: 1900 | C39: 1999 | D39: 1 | F39: 1
A40: Total | B40: 1901 | C40: 1993 | D40: 1 | E40: 1
A41: Total | B41: 1903 | C41: 1993 | D41: 1 | E41: 1
...

Sheet Defunciones generales
A1: year | B1: sex | C1: age | D1: deaths
A2: 2010 | B2: male | C2: 0 | D2: 68
A3: 2010 | B3: male | C3: 1 | D3: 13
A4: 2010 | B4: male | C4: 5 | D4: 8
A5: 2010 | B5: male | C5: 10 | D5: 6
A6: 2010 | B6: male | C6: 15 | D6: 32
A7: 2010 | B7: male | C7: 20 | D7: 45
A8: 2010 | B8: male | C8: 25 | D8: 48
A9: 2010 | B9: male | C9: 30 | D9: 57
A10: 2010 | B10: male | C10: 35 | D10: 90
A11: 2010 | B11: male | C11: 40 | D11: 82
A12: 2010 | B12: male | C12: 45 | D12: 91
A13: 2010 | B13: male | C13: 50 | D13: 119
... A115: 2021 | B115: female | C115: 85 | D115: 604

Sheet Def_hom_filtrada_2010_2019_2021
A2: age | B2: ocu | C2: reg | D2: Total | E2: Hombre | F2: Mujer | G2: No especificado
A3: Total | B3: Total | C3: 1990 | D3: 78 | E3: 76 | F3: 2
A4: Total | B4: Total | C4: 1991 | D4: 99 | E4: 89 | F4: 10
A5: Total | B5: Total | C5: 1992 | D5: 121 | E5: 112 | F5: 9
A6: Total | B6: Total | C6: 1993 | D6: 70 | E6: 64 | F6: 6
A7: Total | B7: Total | C7: 1994 | D7: 78 | E7: 70 | F7: 8
A8: Total | B8: Total | C8: 1995 | D8: 62 | E8: 56 | F8: 6
A9: Total | B9: Total | C9: 1996 | D9: 45 | E9: 40 | F9: 5
A10: Total | B10: Total | C10: 1997 | D10: 51 | E10: 47 | F10: 4
A11: Total | B11: Total | C11: 1998 | D11: 64 | E11: 49 | F11: 14 | G11: 1
A12: Total | B12: Total | C12: 1999 | D12: 60 | E12: 50 | F12: 10
A13: Total | B13: Total | C13: 2000 | D13: 57 | E13: 48 | F13: 9
A14: Total | B14: Total | C14: 2001 | D14: 57 | E14: 48 | F14: 9
A15: Total | B15: Total | C15: 2002 | D15: 43 | E15: 40 | F15: 3
A16: Total | B16: Total | C16: 2003 | D16: 42 | E16: 35 | F16: 7
A17: Total | B17: Total | C17: 2004 | D17: 53 | E17: 47 | F17: 6
A18: Total | B18: Total | C18: 2005 | D18: 49 | E18: 39 | F18: 10
A19: Total | B19: Total | C19: 2006 | D19: 43 | E19: 39 | F19: 4
A20: Total | B20: Total | C20: 2007 | D20: 43 | E20: 37 | F20: 6
A21: Total | B21: Total | C21: 2008 | D21: 56 | E21: 49 | F21: 7
A22: Total | B22: Total | C22: 2009 | D22: 61 | E22: 51 | F22: 10
A23: Total | B23: Total | C23: 2010 | D23: 131 | E23: 126 | F23: 5
A24: Total | B24: Total | C24: 2011 | D24: 169 | E24: 151 | F24: 17 | G24: 1
A25: Total | B25: Total | C25: 2012 | D25: 265 | E25: 240 | F25: 25
A26: Total | B26: Total | C26: 2013 | D26: 227 | E26: 209 | F26: 18
A27: Total | B27: Total | C27: 2014 | D27: 138 | E27: 119 | F27: 19
A28: Total | B28: Total | C28: 2015 | D28: 229 | E28: 203 | F28: 26
A29: Total | B29: Total | C29: 2016 | D29: 612 | E29: 544 | F29: 63 | G29: 5
A30: Total | B30: Total | C30: 2017 | D30: 828 | E30: 750 | F30: 74 | G30: 4
A31: Total | B31: Total | C31: 2018 | D31: 683 | E31: 601 | F31: 81 | G31: 1
A32: Total | B32: Total | C32: 2019 | D32: 706 | E32: 615 | F32: 91
A33: Total | B33: Total | C33: 2020 | D33: 624 | E33: 530 | F33: 94
A34: Total | B34: Total | C34: 2021 | D34: 551 | E34: 490 | F34: 60 | G34: 1
A35: Total | B35: Total | C35: 2022 | D35: 848 | E35: 742 | F35: 106
A36: Total | B36: Total | C36: 2023 | D36: 849 | E36: 720 | F36: 128 | G36: 1
A37: Total | B37: Total | C37: 2024 | D37: 875 | E37: 743 | F37: 132
A38: Total | B38: 1900 | C38: 1998 | D38: 1 | E38: 1
A39: Total | B39: 1990 | C39: 1990 | D39: 64 | E39: 62 | F39: 2
A40: Total | B40: 1991 | C40: 1991 | D40: 84 | E40: 75 | F40: 9
A41: Total | B41: 1992 | C41: 1992 | D41: 77 | E41: 70 | F41: 7
...

Sheet Homicidios
A1: year | B1: sex | C1: age | D1: deaths
A2: 1990 | B2: male | C2: 0 | D2: 0
A3: 1990 | B3: male | C3: 1 | D3: 0
A4: 1990 | B4: male | C4: 5 | D4: 1
A5: 1990 | B5: male | C5: 10 | D5: 1
A6: 1990 | B6: male | C6: 15 | D6: 3
A7: 1990 | B7: male | C7: 20 | D7: 16
A8: 1990 | B8: male | C8: 25 | D8: 5
A9: 1990 | B9: male | C9: 30 | D9: 9
A10: 1990 | B10: male | C10: 35 | D10: 8
A11: 1990 | B11: male | C11: 40 | D11: 4
A12: 1990 | B12: male | C12: 45 | D12: 9
A13: 1990 | B13: male | C13: 50 | D13: 5
... A1331: 2024 | B1331: female | C1331: 85 | D1331: 0

Sheet LT
A1: lt_desc | B1: year | C1: sex | D1: age | E1: mx | F1: qx | G1: ax | H1: lx | I1: dx | J1: Lx | K1: Tx | L1: ex
A2: LT VR/Census, COL | B2: 2010 | C2: m | D2: 0 | E2: 0.013635 | F2: 0.013466 | G2: 0.08 | H2: 100000 | I2: 1347 | J2: 98763 | K2: 7339764 | L2: 73.4
A3: LT VR/Census, COL | B3: 2010 | C3: m | D3: 1 | E3: 0.000546 | F3: 0.002179 | G3: 1.61 | H3: 98653 | I3: 215 | J3: 394100 | K3: 7241001 | L3: 73.4
A4: LT VR/Census, COL | B4: 2010 | C4: m | D4: 5 | E4: 0.000254 | F4: 0.001268 | G4: 2.5 | H4: 98438 | I4: 125 | J4: 491880 | K4: 6846901 | L4: 69.56
A5: LT VR/Census, COL | B5: 2010 | C5: m | D5: 10 | E5: 0.000185 | F5: 0.000926 | G5: 2.5 | H5: 98314 | I5: 91 | J5: 491340 | K5: 6355021 | L5: 64.64
A6: LT VR/Census, COL | B6: 2010 | C6: m | D6: 15 | E6: 0.001019 | F6: 0.005083 | G6: 2.5 | H6: 98222 | I6: 499 | J6: 489864 | K6: 5863681 | L6: 59.7
A7: LT VR/Census, COL | B7: 2010 | C7: m | D7: 20 | E7: 0.001521 | F7: 0.007578 | G7: 2.5 | H7: 97723 | I7: 741 | J7: 486765 | K7: 5373817 | L7: 54.99
A8: LT VR/Census, COL | B8: 2010 | C8: m | D8: 25 | E8: 0.002073 | F8: 0.010314 | G8: 2.5 | H8: 96983 | I8: 1000 | J8: 482413 | K8: 4887052 | L8: 50.39
A9: LT VR/Census, COL | B9: 2010 | C9: m | D9: 30 | E9: 0.002559 | F9: 0.012715 | G9: 2.5 | H9: 95982 | I9: 1220 | J9: 476861 | K9: 4404639 | L9: 45.89
A10: LT VR/Census, COL | B10: 2010 | C10: m | D10: 35 | E10: 0.003478 | F10: 0.017239 | G10: 2.5 | H10: 94762 | I10: 1634 | J10: 469726 | K10: 3927778 | L10: 41.45
A11: LT VR/Census, COL | B11: 2010 | C11: m | D11: 40 | E11: 0.004295 | F11: 0.021247 | G11: 2.5 | H11: 93128 | I11: 1979 | J11: 460696 | K11: 3458051 | L11: 37.13
A12: LT VR/Census, COL | B12: 2010 | C12: m | D12: 45 | E12: 0.005372 | F12: 0.026503 | G12: 2.5 | H12: 91150 | I12: 2416 | J12: 449709 | K12: 2997356 | L12: 32.88
A13: LT VR/Census, COL | B13: 2010 | C13: m | D13: 50 | E13: 0.00711 | F13: 0.034928 | G13: 2.5 | H13: 88734 | I13: 3099 | J13: 435922 | K13: 2547646 | L13: 28.71
... A19: LT VR/Census, COL | B19: 2010 | C19: m | D19: 80 | E19: 0.076526 | F19: 0.321183 | G19: 2.5 | H19: 43032 | I19: 13821 | J19: 180607 | K19: 398394 | L19: 9.26
A20: LT VR/Census, COL | B20: 2010 | C20: m | D20: 85 | E20: 0.134126 | F20: 1 | G20: NA | H20: 29211 | I20: 29211 | J20: 217787 | K20: 217787 | L20: 7.46
A21: LT VR/Census, COL | B21: 2019 | C21: m | D21: 0 | E21: 0.009605 | F21: 0.00952 | G21: 0.07 | H21: 100000 | I21: 952 | J21: 99115 | K21: 7122840 | L21: 71.23
A22: LT VR/Census, COL | B22: 2019 | C22: m | D22: 1 | E22: 0.0005 | F22: 0.001998 | G22: 1.62 | H22: 99048 | I22: 198 | J22: 395722 | K22: 7023724 | L22: 70.91
A23: LT VR/Census, COL | B23: 2019 | C23: m | D23: 5 | E23: 0.000196 | F23: 0.000978 | G23: 2.5 | H23: 98850 | I23: 97 | J23: 494009 | K23: 6628003 | L23: 67.05
A24: LT VR/Census, COL | B24: 2019 | C24: m | D24: 10 | E24: 0.000226 | F24: 0.001129 | G24: 2.5 | H24: 98753 | I24: 111 | J24: 493489 | K24: 6133994 | L24: 62.11
A25: LT VR/Census, COL | B25: 2019 | C25: m | D25: 15 | E25: 0.001819 | F25: 0.009056 | G25: 2.5 | H25: 98642 | I25: 893 | J25: 490976 | K25: 5640505 | L25: 57.18
A26: LT VR/Census, COL | B26: 2019 | C26: m | D26: 20 | E26: 0.004179 | F26: 0.020678 | G26: 2.5 | H26: 97749 | I26: 2021 | J26: 483690 | K26: 5149529 | L26: 52.68
A27: LT VR/Census, COL | B27: 2019 | C27: m | D27: 25 | E27: 0.005135 | F27: 0.025348 | G27: 2.5 | H27: 95727 | I27: 2427 | J27: 472571 | K27: 4665839 | L27: 48.74
A28: LT VR/Census, COL | B28: 2019 | C28: m | D28: 30 | E28: 0.005055 | F28: 0.024962 | G28: 2.5 | H28: 93301 | I28: 2329 | J28: 460682 | K28: 4193268 | L28: 44.94
A29: LT VR/Census, COL | B29: 2019 | C29: m | D29: 35 | E29: 0.004761 | F29: 0.023524 | G29: 2.5 | H29: 90972 | I29: 2140 | J29: 449509 | K29: 3732587 | L29: 41.03
A30: LT VR/Census, COL | B30: 2019 | C30: m | D30: 40 | E30: 0.006298 | F30: 0.031001 | G30: 2.5 | H30: 88832 | I30: 2754 | J30: 437275 | K30: 3283077 | L30: 36.96
A31: LT VR/Census, COL | B31: 2019 | C31: m | D31: 45 | E31: 0.00669 | F31: 0.032899 | G31: 2.5 | H31: 86078 | I31: 2832 | J31: 423310 | K31: 2845803 | L31: 33.06
A32: LT VR/Census, COL | B32: 2019 | C32: m | D32: 50 | E32: 0.008233 | F32: 0.040335 | G32: 2.5 | H32: 83246 | I32: 3358 | J32: 407836 | K32: 2422493 | L32: 29.1
... A38: LT VR/Census, COL | B38: 2019 | C38: m | D38: 80 | E38: 0.061666 | F38: 0.267144 | G38: 2.5 | H38: 42742 | I38: 11418 | J38: 185166 | K38: 400669 | L38: 9.37
A39: LT VR/Census, COL | B39: 2019 | C39: m | D39: 85 | E39: 0.145354 | F39: 1 | G39: NA | H39: 31324 | I39: 31324 | J39: 215502 | K39: 215502 | L39: 6.88
A40: LT VR/Census, COL | B40: 2021 | C40: m | D40: 0 | E40: 0.010805 | F40: 0.010698 | G40: 0.07 | H40: 100000 | I40: 1070 | J40: 99009 | K40: 6588000 | L40: 65.88
A41: LT VR/Census, COL | B41: 2021 | C41: m | D41: 1 | E41: 0.000511 | F41: 0.002041 | G41: 1.62 | H41: 98930 | I41: 202 | J41: 395240 | K41: 6488991 | L41: 65.59
A42: LT VR/Census, COL | B42: 2021 | C42: m | D42: 5 | E42: 0.000293 | F42: 0.001466 | G42: 2.5 | H42: 98728 | I42: 145 | J42: 493280 | K42: 6093750 | L42: 61.72
A43: LT VR/Census, COL | B43: 2021 | C43: m | D43: 10 | E43: 0.000258 | F43: 0.001291 | G43: 2.5 | H43: 98584 | I43: 127 | J43: 492600 | K43: 5600471 | L43: 56.81
A44: LT VR/Census, COL | B44: 2021 | C44: m | D44: 15 | E44: 0.001638 | F44: 0.008155 | G44: 2.5 | H44: 98456 | I44: 803 | J44: 490274 | K44: 5107871 | L44: 51.88
A45: LT VR/Census, COL | B45: 2021 | C45: m | D45: 20 | E45: 0.00415 | F45: 0.020538 | G45: 2.5 | H45: 97653 | I45: 2006 | J45: 483253 | K45: 4617597 | L45: 47.29
A46: LT VR/Census, COL | B46: 2021 | C46: m | D46: 25 | E46: 0.005462 | F46: 0.02694 | G46: 2.5 | H46: 95648 | I46: 2577 | J46: 471797 | K46: 4134344 | L46: 43.22
A47: LT VR/Census, COL | B47: 2021 | C47: m | D47: 30 | E47: 0.005514 | F47: 0.027194 | G47: 2.5 | H47: 93071 | I47: 2531 | J47: 459027 | K47: 3662547 | L47: 39.35
A48: LT VR/Census, COL | B48: 2021 | C48: m | D48: 35 | E48: 0.006924 | F48: 0.03403 | G48: 2.5 | H48: 90540 | I48: 3081 | J48: 444997 | K48: 3203520 | L48: 35.38
A49: LT VR/Census, COL | B49: 2021 | C49: m | D49: 40 | E49: 0.007852 | F49: 0.038504 | G49: 2.5 | H49: 87459 | I49: 3367 | J49: 428876 | K49: 2758523 | L49: 31.54
A50: LT VR/Census, COL | B50: 2021 | C50: m | D50: 45 | E50: 0.008538 | F50: 0.041798 | G50: 2.5 | H50: 84091 | I50: 3515 | J50: 411670 | K50: 2329647 | L50: 27.7
...

Sheet Decrementos Múltiples
B2: Hombres, 2019
B3: Age x | C3: n | D3: nDx | E3: nDxi | I3: nqx | K3: e0 | M3: nqx_i | O3: ndx_i | Q3: L | R3: T | S3: e0_i | T3: diff
B4: 0 | C4: 1 | D4: ='Defunciones generales'!D21 -> 46 | E4: =Homicidios!D553 -> 0 | F4: =(D4-E4)/D4 -> 1 | G4: =LT!H21 -> 100000 | H4: =1-LT!F21 -> 0.99048 | I4: =1-H4 -> 0.00952 | J4: =LT!G21 -> 0.07 | K4: =LT!L21 -> 71.23 | L4: =H4^F4 -> 0.99048 | M4: =1-L4 -> 0.00952 | N4: 100000 | O4: =N4*M4 -> 952 | P4: =C4+(F4*(I4/M4)*(J4-C4)) -> 0.07 | Q4: =(C4*N5)+(P4*O4) -> 99114.64 | R4: =R5+Q4 -> 7528599.6 | S4: =R4/N4 -> 75.285996 | T4: =S4-K4 -> 4.0559957
B5: 1 | C5: 4 | D5: ='Defunciones generales'!D22 -> 11 | E5: =Homicidios!D554 -> 0 | F5: =(D5-E5)/D5 -> 1 | G5: =LT!H22 -> 99048 | H5: =1-LT!F22 -> 0.998002 | I5: =1-H5 -> 0.001998 | J5: =LT!G22 -> 1.62 | K5: =LT!L22 -> 70.91 | L5: =H5^F5 -> 0.998002 | M5: =1-L5 -> 0.001998 | N5: =N4*L4 -> 99048 | O5: =N5*M5 -> 197.8979 | P5: =C5+(F5*(I5/M5)*(J5-C5)) -> 1.62 | Q5: =(C5*N6)+(P5*O5) -> 395721 | R5: =R6+Q5 -> 7429484.9 | S5: =R5/N5 -> 75.008934 | T5: =S5-K5 -> 4.0989344
B6: 5 | C6: 5 | D6: ='Defunciones generales'!D23 -> 6 | E6: =Homicidios!D555 -> 0 | F6: =(D6-E6)/D6 -> 1 | G6: =LT!H23 -> 98850 | H6: =1-LT!F23 -> 0.999022 | I6: =1-H6 -> 0.000978 | J6: =LT!G23 -> 2.5 | K6: =LT!L23 -> 67.05 | L6: =H6^F6 -> 0.999022 | M6: =1-L6 -> 0.000978 | N6: =N5*L5 -> 98850.102 | O6: =N6*M6 -> 96.6754 | P6: =C6+(F6*(I6/M6)*(J6-C6)) -> 2.5 | Q6: =(C6*N7)+(P6*O6) -> 494008.82 | R6: =R7+Q6 -> 7033763.9 | S6: =R6/N6 -> 71.155859 | T6: =S6-K6 -> 4.105859
B7: 10 | C7: 5 | D7: ='Defunciones generales'!D24 -> 7 | E7: =Homicidios!D556 -> 1 | F7: =(D7-E7)/D7 -> 0.85714286 | G7: =LT!H24 -> 98753 | H7: =1-LT!F24 -> 0.998871 | I7: =1-H7 -> 0.001129 | J7: =LT!G24 -> 2.5 | K7: =LT!L24 -> 62.11 | L7: =H7^F7 -> 0.99903221 | M7: =1-L7 -> 0.00096779236 | N7: =N6*L6 -> 98753.427 | O7: =N7*M7 -> 95.572812 | P7: =(((-5/24)*O6)+((2.5)*O7)+((5/24)*O8))/O7 -> 3.2988375 | Q7: =(C7*N8)+(P7*O7) -> 493604.55 | R7: =R8+Q7 -> 6539755.1 | S7: =R7/N7 -> 66.22307 | T7: =S7-K7 -> 4.1130702
B8: 15 | C8: 5 | D8: ='Defunciones generales'!D25 -> 58 | E8: =Homicidios!D557 -> 28 | F8: =(D8-E8)/D8 -> 0.51724138 | G8: =LT!H25 -> 98642 | H8: =1-LT!F25 -> 0.990944 | I8: =1-H8 -> 0.009056 | J8: =LT!G25 -> 2.5 | K8: =LT!L25 -> 57.18 | L8: =H8^F8 -> 0.99530558 | M8: =1-L8 -> 0.0046944232 | N8: =N7*L7 -> 98657.854 | O8: =N8*M8 -> 463.14172 | P8: =(((-5/24)*O7)+((2.5)*O8)+((5/24)*O9))/O8 -> 2.7848942 | Q8: =(C8*N9)+(P8*O8) -> 492263.36 | R8: =R9+Q8 -> 6046150.6 | S8: =R8/N8 -> 61.284027 | T8: =S8-K8 -> 4.1040267
B9: 20 | C9: 5 | D9: ='Defunciones generales'!D26 -> 129 | E9: =Homicidios!D558 -> 83 | F9: =(D9-E9)/D9 -> 0.35658915 | G9: =LT!H26 -> 97749 | H9: =1-LT!F26 -> 0.979322 | I9: =1-H9 -> 0.020678 | J9: =LT!G26 -> 2.5 | K9: =LT!L26 -> 52.68 | L9: =H9^F9 -> 0.99257684 | M9: =1-L9 -> 0.0074231642 | N9: =N8*L8 -> 98194.712 | O9: =N9*M9 -> 728.91547 | P9: =(((-5/24)*O8)+((2.5)*O9)+((5/24)*O10))/O9 -> 2.592324 | Q9: =(C9*N10)+(P9*O9) -> 489218.57 | R9: =R10+Q9 -> 5553887.2 | S9: =R9/N9 -> 56.559942 | T9: =S9-K9 -> 3.8799417
B10: 25 | C10: 5 | D10: ='Defunciones generales'!D27 -> 149 | E10: =Homicidios!D559 -> 102 | F10: =(D10-E10)/D10 -> 0.31543624 | G10: =LT!H27 -> 95727 | H10: =1-LT!F27 -> 0.974652 | I10: =1-H10 -> 0.025348 | J10: =LT!G27 -> 2.5 | K10: =LT!L27 -> 48.74 | L10: =H10^F10 -> 0.99193395 | M10: =1-L10 -> 0.0080660542 | N10: =N9*L9 -> 97465.797 | O10: =N10*M10 -> 786.16439 | P10: =(((-5/24)*O9)+((2.5)*O10)+((5/24)*O11))/O10 -> 2.5263668 | Q10: =(C10*N11)+(P10*O10) -> 485384.3 | R10: =R11+Q10 -> 5064668.6 | S10: =R10/N10 -> 51.963548 | T10: =S10-K10 -> 3.2235482
B11: 30 | C11: 5 | D11: ='Defunciones generales'!D28 -> 141 | E11: =Homicidios!D560 -> 93 | F11: =(D11-E11)/D11 -> 0.34042553 | G11: =LT!H28 -> 93301 | H11: =1-LT!F28 -> 0.975038 | I11: =1-H11 -> 0.024962 | J11: =LT!G28 -> 2.5 | K11: =LT!L28 -> 44.94 | L11: =H11^F11 -> 0.99143136 | M11: =1-L11 -> 0.0085686388 | N11: =N10*L10 -> 96679.632 | O11: =N11*M11 -> 828.41285 | P11: =(((-5/24)*O10)+((2.5)*O11)+((5/24)*O12))/O11 -> 2.5674031 | Q11: =(C11*N12)+(P11*O11) -> 481382.97 | R11: =R12+Q11 -> 4579284.3 | S11: =R11/N11 -> 47.365554 | T11: =S11-K11 -> 2.4255538
B12: 35 | C12: 5 | D12: ='Defunciones generales'!D29 -> 127 | E12: =Homicidios!D561 -> 68 | F12: =(D12-E12)/D12 -> 0.46456693 | G12: =LT!H29 -> 90972 | H12: =1-LT!F29 -> 0.976476 | I12: =1-H12 -> 0.023524 | J12: =LT!G29 -> 2.5 | K12: =LT!L29 -> 41.03 | L12: =H12^F12 -> 0.98900186 | M12: =1-L12 -> 0.010998139 | N12: =N11*L11 -> 95851.219 | O12: =N12*M12 -> 1054.185 | P12: =(((-5/24)*O11)+((2.5)*O12)+((5/24)*O13))/O12 -> 2.6587199 | Q12: =(C12*N13)+(P12*O12) -> 476787.95 | R12: =R13+Q12 -> 4097901.4 | S12: =R12/N12 -> 42.752731 | T12: =S12-K12 -> 1.7227306
B13: 40 | C13: 5 | D13: ='Defunciones generales'!D30 -> 156 | E13: =Homicidios!D562 -> 70 | F13: =(D13-E13)/D13 -> 0.55128205 | G13: =LT!H30 -> 88832 | H13: =1-LT!F30 -> 0.968999 | I13: =1-H13 -> 0.031001 | J13: =LT!G30 -> 2.5 | K13: =LT!L30 -> 36.96 | L13: =H13^F13 -> 0.98278902 | M13: =1-L13 -> 0.017210978 | N13: =N12*L12 -> 94797.034 | O13: =N13*M13 -> 1631.5497 | P13: =(((-5/24)*O12)+((2.5)*O13)+((5/24)*O14))/O13 -> 2.6404726 | Q13: =(C13*N14)+(P13*O13) -> 470135.49 | R13: =R14+Q13 -> 3621113.4 | S13: =R13/N13 -> 38.198594 | T13: =S13-K13 -> 1.2385937
B14: 45 | C14: 5 | D14: ='Defunciones generales'!D31 -> 153 | E14: =Homicidios!D563 -> 46 | F14: =(D14-E14)/D14 -> 0.69934641 | G14: =LT!H31 -> 86078 | H14: =1-LT!F31 -> 0.967101 | I14: =1-H14 -> 0.032899 | J14: =LT!G31 -> 2.5 | K14: =LT!L31 -> 33.06 | L14: =H14^F14 -> 0.97687676 | M14: =1-L14 -> 0.023123239 | N14: =N13*L13 -> 93165.485 | O14: =N14*M14 -> 2154.2878 | P14: =(((-5/24)*O13)+((2.5)*O14)+((5/24)*O15))/O14 -> 2.6492711 | Q14: =(C14*N15)+(P14*O14) -> 460763.28 | R14: =R15+Q14 -> 3150977.9 | S14: =R14/N14 -> 33.821301 | T14: =S14-K14 -> 0.76130114
B15: 50 | C15: 5 | D15: ='Defunciones generales'!D32 -> 160 | E15: =Homicidios!D564 -> 22 | F15: =(D15-E15)/D15 -> 0.8625 | G15: =LT!H32 -> 83246 | H15: =1-LT!F32 -> 0.959665 | I15: =1-H15 -> 0.040335 | J15: =LT!G32 -> 2.5 | K15: =LT!L32 -> 29.1 | L15: =H15^F15 -> 0.96511308 | M15: =1-L15 -> 0.034886916 | N15: =N14*L14 -> 91011.197 | O15: =N15*M15 -> 3175.1 | P15: =(((-5/24)*O14)+((2.5)*O15)+((5/24)*O16))/O15 -> 2.6644837 | Q15: =(C15*N16)+(P15*O15) -> 447640.49 | R15: =R16+Q15 -> 2690214.6 | S15: =R15/N15 -> 29.559161 | T15: =S15-K15 -> 0.45916116
B16: 55 | C16: 5 | D16: ='Defunciones generales'!D33 -> 202 | E16: =Homicidios!D565 -> 23 | F16: =(D16-E16)/D16 -> 0.88613861 | G16: =LT!H33 -> 79888 | H16: =1-LT!F33 -> 0.940323 | I16: =1-H16 -> 0.059677 | J16: =LT!G33 -> 2.5 | K16: =LT!L33 -> 25.22 | L16: =H16^F16 -> 0.94693413 | M16: =1-L16 -> 0.05306587 | N16: =N15*L15 -> 87836.097 | O16: =N16*M16 -> 4661.0989 | P16: =(((-5/24)*O15)+((2.5)*O16)+((5/24)*O17))/O16 -> 2.6378472 | Q16: =(C16*N17)+(P16*O16) -> 428170.26 | R16: =R17+Q16 -> 2242574.2 | S16: =R16/N16 -> 25.53135 | T16: =S16-K16 -> 0.3113502
B17: 60 | C17: 5 | D17: ='Defunciones generales'!D34 -> 233 | E17: =Homicidios!D566 -> 15 | F17: =(D17-E17)/D17 -> 0.93562232 | G17: =LT!H34 -> 75121 | H17: =1-LT!F34 -> 0.919782 | I17: =1-H17 -> 0.080218 | J17: =LT!G34 -> 2.5 | K17: =LT!L34 -> 21.66 | L17: =H17^F17 -> 0.92474669 | M17: =1-L17 -> 0.075253305 | N17: =N16*L16 -> 83174.998 | O17: =N17*M17 -> 6259.1935 | P17: =(((-5/24)*O16)+((2.5)*O17)+((5/24)*O18))/O17 -> 2.5755432 | Q17: =(C17*N18)+(P17*O17) -> 400699.85 | R17: =R18+Q17 -> 1814403.9 | S17: =R17/N17 -> 21.814294 | T17: =S17-K17 -> 0.1542944
B18: 65 | C18: 5 | D18: ='Defunciones generales'!D35 -> 194 | E18: =Homicidios!D567 -> 0 | F18: =(D18-E18)/D18 -> 1 | G18: =LT!H35 -> 69095 | H18: =1-LT!F35 -> 0.909892 | I18: =1-H18 -> 0.090108 | J18: =LT!G35 -> 2.5 | K18: =LT!L35 -> 18.33 | L18: =H18^F18 -> 0.909892 | M18: =1-L18 -> 0.090108 | N18: =N17*L17 -> 76915.805 | O18: =N18*M18 -> 6930.7293 | P18: =(((-5/24)*O17)+((2.5)*O18)+((5/24)*O19))/O18 -> 2.595304 | Q18: =(C18*N19)+(P18*O18) -> 367912.73 | R18: =R19+Q18 -> 1413704 | S18: =R18/N18 -> 18.37989 | T18: =S18-K18 -> 0.049890274
... B20: 75 | C20: 5 | D20: ='Defunciones generales'!D37 -> 235 | E20: =Homicidios!D569 -> 1 | F20: =(D20-E20)/D20 -> 0.99574468 | G20: =LT!H37 -> 54398 | H20: =1-LT!F37 -> 0.785738 | I20: =1-H20 -> 0.214262 | J20: =LT!G37 -> 2.5 | K20: =LT!L37 -> 11.83 | L20: =H20^F20 -> 0.78654465 | M20: =1-L20 -> 0.21345535 | N20: =N19*L19 -> 60555.356 | O20: =N20*M20 -> 12925.865 | P20: =(((-5/24)*O19)+((2.5)*O20)+((5/24)*O21))/O20 -> 2.5521487 | Q20: =(C20*N21)+(P20*O20) -> 271136.19 | R20: =R21+Q20 -> 718191.26 | S20: =R20/N20 -> 11.860078 | T20: =S20-K20 -> 0.03007816
B21: 80 | C21: 5 | D21: ='Defunciones generales'!D38 -> 185 | E21: =Homicidios!D570 -> 1 | F21: =(D21-E21)/D21 -> 0.99459459 | G21: =LT!H38 -> 42742 | H21: =1-LT!F38 -> 0.732856 | I21: =1-H21 -> 0.267144 | J21: =LT!G38 -> 2.5 | K21: =LT!L38 -> 9.37 | L21: =H21^F21 -> 0.73408826 | M21: =1-L21 -> 0.26591174 | N21: =N20*L20 -> 47629.492 | O21: =N21*M21 -> 12665.241 | P21: =C21+(F21*(I21/M21)*(J21-C21)) -> 2.5019909 | Q21: =(C21*N22)+(P21*O21) -> 206509.57 | R21: =R22+Q21 -> 447055.07 | S21: =R21/N21 -> 9.3860979 | T21: =S21-K21 -> 0.016097873
B22: 85 | C22: 5 | D22: ='Defunciones generales'!D39 -> 359 | E22: =Homicidios!D571 -> 0 | F22: =(D22-E22)/D22 -> 1 | G22: =LT!H39 -> 31324 | H22: =1-LT!F39 -> 0 | I22: =1-H22 -> 1 | J22: =LT!G39 -> NA | K22: =LT!L39 -> 6.88 | L22: =H22^F22 -> 0 | M22: =1-L22 -> 1 | N22: =N21*L21 -> 34964.251 | O22: =N22*M22 -> 34964.251 | P22: =K22/F22 -> 6.88 | Q22: =N22/LT!E39 -> 240545.5 | R22: =Q22 -> 240545.5 | S22: =R22/N22 -> 6.8797556 | T22: =S22-K22 -> -0.00024436892
B26: Mujeres, 2019
B27: Age x | C27: n | D27: nDx | E27: nDxi | I27: nqx | K27: e0 | M27: nqx_i | O27: ndx_i | Q27: L | R27: T | S27: e0_i | T27: diff
B28: 0 | C28: 1 | D28: ='Defunciones generales'!D78 -> 34 | E28: =Homicidios!D1218 -> 0 | F28: =(D28-E28)/D28 -> 1 | G28: =LT!H78 -> 100000 | H28: =1-LT!F78 -> 0.9927 | I28: =1-H28 -> 0.0073 | J28: =LT!G78 -> 0.07 | K28: =LT!L78 -> 79.89 | L28: =H28^F28 -> 0.9927 | M28: =1-L28 -> 0.0073 | N28: 100000 | O28: =N28*M28 -> 730 | P28: =C28+(F28*(I28/M28)*(J28-C28)) -> 0.07 | Q28: =(C28*N29)+(P28*O28) -> 99321.1 | R28: =R29+Q28 -> 8064976.3 | S28: =R28/N28 -> 80.649763 | T28: =S28-K28 -> 0.75976298 | X28: Hombres | Y28: Mujeres
B29: 1 | C29: 4 | D29: ='Defunciones generales'!D79 -> 17 | E29: =Homicidios!D1219 -> 1 | F29: =(D29-E29)/D29 -> 0.94117647 | G29: =LT!H79 -> 99270 | H29: =1-LT!F79 -> 0.996825 | I29: =1-H29 -> 0.003175 | J29: =LT!G79 -> 1.51 | K29: =LT!L79 -> 79.48 | L29: =H29^F29 -> 0.99701149 | M29: =1-L29 -> 0.0029885147 | N29: =N28*L28 -> 99270 | O29: =N29*M29 -> 296.66985 | P29: =C29+(F29*(I29/M29)*(J29-C29)) -> 1.5102328 | Q29: =(C29*N30)+(P29*O29) -> 396341.36 | R29: =R30+Q29 -> 7965655.2 | S29: =R29/N29 -> 80.242321 | T29: =S29-K29 -> 0.76232093 | W29: Sin homicidios | X29: =S4 -> 75.285996 | Y29: =S28 -> 80.649763
B30: 5 | C30: 5 | D30: ='Defunciones generales'!D80 -> 8 | E30: =Homicidios!D1220 -> 0 | F30: =(D30-E30)/D30 -> 1 | G30: =LT!H80 -> 98955 | H30: =1-LT!F80 -> 0.998642 | I30: =1-H30 -> 0.001358 | J30: =LT!G80 -> 2.5 | K30: =LT!L80 -> 75.73 | L30: =H30^F30 -> 0.998642 | M30: =1-L30 -> 0.001358 | N30: =N29*L29 -> 98973.33 | O30: =N30*M30 -> 134.40578 | P30: =C30+(F30*(I30/M30)*(J30-C30)) -> 2.5 | Q30: =(C30*N31)+(P30*O30) -> 494530.64 | R30: =R31+Q30 -> 7569313.8 | S30: =R30/N30 -> 76.478318 | T30: =S30-K30 -> 0.74831821 | W30: Con homicidios | X30: =K4 -> 71.23 | Y30: =K28 -> 79.89
B31: 10 | C31: 5 | D31: ='Defunciones generales'!D81 -> 5 | E31: =Homicidios!D1221 -> 1 | F31: =(D31-E31)/D31 -> 0.8 | G31: =LT!H81 -> 98820 | H31: =1-LT!F81 -> 0.999161 | I31: =1-H31 -> 0.000839 | J31: =LT!G81 -> 2.5 | K31: =LT!L81 -> 70.82 | L31: =H31^F31 -> 0.99932874 | M31: =1-L31 -> 0.00067125633 | N31: =N30*L30 -> 98838.924 | O31: =N31*M31 -> 66.346254 | P31: =(((-5/24)*O30)+((2.5)*O31)+((5/24)*O32))/O31 -> 2.4145356 | Q31: =(C31*N32)+(P31*O31) -> 494023.09 | R31: =R32+Q31 -> 7074783.2 | S31: =R31/N31 -> 71.578917 | T31: =S31-K31 -> 0.75891738 | X31: =X29-X30 -> 4.0559957 | Y31: =Y29-Y30 -> 0.75976298
B32: 15 | C32: 5 | D32: ='Defunciones generales'!D82 -> 15 | E32: =Homicidios!D1222 -> 8 | F32: =(D32-E32)/D32 -> 0.46666667 | G32: =LT!H82 -> 98738 | H32: =1-LT!F82 -> 0.997676 | I32: =1-H32 -> 0.002324 | J32: =LT!G82 -> 2.5 | K32: =LT!L82 -> 65.88 | L32: =H32^F32 -> 0.99891479 | M32: =1-L32 -> 0.0010852063 | N32: =N31*L31 -> 98772.578 | O32: =N32*M32 -> 107.18862 | P32: =(((-5/24)*O31)+((2.5)*O32)+((5/24)*O33))/O32 -> 2.9465247 | Q32: =(C32*N33)+(P32*O32) -> 493642.78 | R32: =R33+Q32 -> 6580760.1 | S32: =R32/N32 -> 66.625376 | T32: =S32-K32 -> 0.74537559
B33: 20 | C33: 5 | D33: ='Defunciones generales'!D83 -> 35 | E33: =Homicidios!D1223 -> 16 | F33: =(D33-E33)/D33 -> 0.54285714 | G33: =LT!H83 -> 98508 | H33: =1-LT!F83 -> 0.994479 | I33: =1-H33 -> 0.005521 | J33: =LT!G83 -> 2.5 | K33: =LT!L83 -> 61.03 | L33: =H33^F33 -> 0.99699909 | M33: =1-L33 -> 0.0030009066 | N33: =N32*L32 -> 98665.389 | O33: =N33*M33 -> 296.08562 | P33: =(((-5/24)*O32)+((2.5)*O33)+((5/24)*O34))/O33 -> 2.6205048 | Q33: =(C33*N34)+(P33*O33) -> 492622.41 | R33: =R34+Q33 -> 6087117.3 | S33: =R33/N33 -> 61.694555 | T33: =S33-K33 -> 0.66455535
B34: 25 | C34: 5 | D34: ='Defunciones generales'!D84 -> 39 | E34: =Homicidios!D1224 -> 21 | F34: =(D34-E34)/D34 -> 0.46153846 | G34: =LT!H84 -> 97964 | H34: =1-LT!F84 -> 0.993877 | I34: =1-H34 -> 0.006123 | J34: =LT!G84 -> 2.5 | K34: =LT!L84 -> 56.35 | L34: =H34^F34 -> 0.99716933 | M34: =1-L34 -> 0.0028306733 | N34: =N33*L33 -> 98369.304 | O34: =N34*M34 -> 278.45137 | P34: =(((-5/24)*O33)+((2.5)*O34)+((5/24)*O35))/O34 -> 2.518936 | Q34: =(C34*N35)+(P34*O34) -> 491155.66 | R34: =R35+Q34 -> 5594494.9 | S34: =R34/N34 -> 56.872365 | T34: =S34-K34 -> 0.52236465
B35: 30 | C35: 5 | D35: ='Defunciones generales'!D85 -> 31 | E35: =Homicidios!D1225 -> 11 | F35: =(D35-E35)/D35 -> 0.64516129 | G35: =LT!H85 -> 97364 | H35: =1-LT!F85 -> 0.994926 | I35: =1-H35 -> 0.005074 | J35: =LT!G85 -> 2.5 | K35: =LT!L85 -> 51.69 | L35: =H35^F35 -> 0.9967235 | M35: =1-L35 -> 0.0032765021 | N35: =N34*L34 -> 98090.853 | O35: =N35*M35 -> 321.39488 | P35: =(((-5/24)*O34)+((2.5)*O35)+((5/24)*O36))/O35 -> 2.6175864 | Q35: =(C35*N36)+(P35*O35) -> 489688.57 | R35: =R36+Q35 -> 5103339.3 | S35: =R35/N35 -> 52.026658 | T35: =S35-K35 -> 0.33665821
B36: 35 | C36: 5 | D36: ='Defunciones generales'!D86 -> 32 | E36: =Homicidios!D1226 -> 5 | F36: =(D36-E36)/D36 -> 0.84375 | G36: =LT!H86 -> 96870 | H36: =1-LT!F86 -> 0.994428 | I36: =1-H36 -> 0.005572 | J36: =LT!G86 -> 2.5 | K36: =LT!L86 -> 46.94 | L36: =H36^F36 -> 0.99529657 | M36: =1-L36 -> 0.004703426 | N36: =N35*L35 -> 97769.458 | O36: =N36*M36 -> 459.85141 | P36: =(((-5/24)*O35)+((2.5)*O36)+((5/24)*O37))/O36 -> 2.6499223 | Q36: =(C36*N37)+(P36*O36) -> 487766.6 | R36: =R37+Q36 -> 4613650.7 | S36: =R36/N36 -> 47.189079 | T36: =S36-K36 -> 0.24907931
B37: 40 | C37: 5 | D37: ='Defunciones generales'!D87 -> 44 | E37: =Homicidios!D1227 -> 9 | F37: =(D37-E37)/D37 -> 0.79545455 | G37: =LT!H87 -> 96331 | H37: =1-LT!F87 -> 0.99158 | I37: =1-H37 -> 0.00842 | J37: =LT!G87 -> 2.5 | K37: =LT!L87 -> 42.19 | L37: =H37^F37 -> 0.99329649 | M37: =1-L37 -> 0.0067035145 | N37: =N36*L36 -> 97309.606 | O37: =N37*M37 -> 652.31636 | P37: =(((-5/24)*O36)+((2.5)*O37)+((5/24)*O38))/O37 -> 2.7885754 | Q37: =(C37*N38)+(P37*O37) -> 485105.48 | R37: =R38+Q37 -> 4125884.1 | S37: =R37/N37 -> 42.399556 | T37: =S37-K37 -> 0.2095559
B38: 45 | C38: 5 | D38: ='Defunciones generales'!D88 -> 73 | E38: =Homicidios!D1228 -> 7 | F38: =(D38-E38)/D38 -> 0.90410959 | G38: =LT!H88 -> 95519 | H38: =1-LT!F88 -> 0.98441 | I38: =1-H38 -> 0.01559 | J38: =LT!G88 -> 2.5 | K38: =LT!L88 -> 37.52 | L38: =H38^F38 -> 0.98589434 | M38: =1-L38 -> 0.014105665 | N38: =N37*L37 -> 96657.29 | O38: =N38*M38 -> 1363.4153 | P38: =(((-5/24)*O37)+((2.5)*O38)+((5/24)*O39))/O38 -> 2.6711443 | Q38: =(C38*N39)+(P38*O38) -> 480111.25 | R38: =R39+Q38 -> 3640778.6 | S38: =R38/N38 -> 37.666881 | T38: =S38-K38 -> 0.1468807
B39: 50 | C39: 5 | D39: ='Defunciones generales'!D89 -> 80 | E39: =Homicidios!D1229 -> 1 | F39: =(D39-E39)/D39 -> 0.9875 | G39: =LT!H89 -> 94030 | H39: =1-LT!F89 -> 0.981168 | I39: =1-H39 -> 0.018832 | J39: =LT!G89 -> 2.5 | K39: =LT!L89 -> 33.08 | L39: =H39^F39 -> 0.9814012 | M39: =1-L39 -> 0.018598803 | N39: =N38*L38 -> 95293.875 | O39: =N39*M39 -> 1772.352 | P39: =(((-5/24)*O38)+((2.5)*O39)+((5/24)*O40))/O39 -> 2.6195811 | Q39: =(C39*N40)+(P39*O39) -> 472250.43 | R39: =R40+Q39 -> 3160667.4 | S39: =R39/N39 -> 33.167582 | T39: =S39-K39 -> 0.087581535
B40: 55 | C40: 5 | D40: ='Defunciones generales'!D90 -> 91 | E40: =Homicidios!D1230 -> 2 | F40: =(D40-E40)/D40 -> 0.97802198 | G40: =LT!H90 -> 92260 | H40: =1-LT!F90 -> 0.973979 | I40: =1-H40 -> 0.026021 | J40: =LT!G90 -> 2.5 | K40: =LT!L90 -> 28.67 | L40: =H40^F40 -> 0.97454355 | M40: =1-L40 -> 0.025456452 | N40: =N39*L39 -> 93521.523 | O40: =N40*M40 -> 2380.7262 | P40: =(((-5/24)*O39)+((2.5)*O40)+((5/24)*O41))/O40 -> 2.6926164 | Q40: =(C40*N41)+(P40*O40) -> 462114.36 | R40: =R41+Q40 -> 2688416.9 | S40: =R40/N40 -> 28.746505 | T40: =S40-K40 -> 0.076505058
B41: 60 | C41: 5 | D41: ='Defunciones generales'!D91 -> 133 | E41: =Homicidios!D1231 -> 1 | F41: =(D41-E41)/D41 -> 0.9924812 | G41: =LT!H91 -> 89859 | H41: =1-LT!F91 -> 0.95608 | I41: =1-H41 -> 0.04392 | J41: =LT!G91 -> 2.5 | K41: =LT!L91 -> 24.36 | L41: =H41^F41 -> 0.95640292 | M41: =1-L41 -> 0.04359708 | N41: =N40*L40 -> 91140.796 | O41: =N41*M41 -> 3973.4726 | P41: =(((-5/24)*O40)+((2.5)*O41)+((5/24)*O42))/O41 -> 2.6897114 | Q41: =(C41*N42)+(P41*O41) -> 446524.11 | R41: =R42+Q41 -> 2226302.6 | S41: =R41/N41 -> 24.427069 | T41: =S41-K41 -> 0.067069387
B42: 65 | C42: 5 | D42: ='Defunciones generales'!D92 -> 158 | E42: =Homicidios!D1232 -> 0 | F42: =(D42-E42)/D42 -> 1 | G42: =LT!H92 -> 85912 | H42: =1-LT!F92 -> 0.931178 | I42: =1-H42 -> 0.068822 | J42: =LT!G92 -> 2.5 | K42: =LT!L92 -> 20.37 | L42: =H42^F42 -> 0.931178 | M42: =1-L42 -> 0.068822 | N42: =N41*L41 -> 87167.324 | O42: =N42*M42 -> 5999.0296 | P42: =(((-5/24)*O41)+((2.5)*O42)+((5/24)*O43))/O42 -> 2.6173649 | Q42: =(C42*N43)+(P42*O42) -> 421543.12 | R42: =R43+Q42 -> 1779778.4 | S42: =R42/N42 -> 20.417954 | T42: =S42-K42 -> 0.047954419
B43: 70 | C43: 5 | D43: ='Defunciones generales'!D93 -> 153 | E43: =Homicidios!D1233 -> 0 | F43: =(D43-E43)/D43 -> 1 | G43: =LT!H93 -> 80000 | H43: =1-LT!F93 -> 0.90941 | I43: =1-H43 -> 0.09059 | J43: =LT!G93 -> 2.5 | K43: =LT!L93 -> 16.69 | L43: =H43^F43 -> 0.90941 | M43: =1-L43 -> 0.09059 | N43: =N42*L42 -> 81168.294 | O43: =N43*M43 -> 7353.0358 | P43: =(((-5/24)*O42)+((2.5)*O43)+((5/24)*O44))/O43 -> 2.6709611 | Q43: =(C43*N44)+(P43*O43) -> 388715.96 | R43: =R44+Q43 -> 1358235.3 | S43: =R43/N43 -> 16.73357 | T43: =S43-K43 -> 0.043569876
B44: 75 | C44: 5 | D44: ='Defunciones generales'!D94 -> 197 | E44: =Homicidios!D1234 -> 1 | F44: =(D44-E44)/D44 -> 0.99492386 | G44: =LT!H94 -> 72752 | H44: =1-LT!F94 -> 0.836225 | I44: =1-H44 -> 0.163775 | J44: =LT!G94 -> 2.5 | K44: =LT!L94 -> 13.1 | L44: =H44^F44 -> 0.83698456 | M44: =1-L44 -> 0.16301544 | N44: =N43*L43 -> 73815.258 | O44: =N44*M44 -> 12033.027 | P44: =(((-5/24)*O43)+((2.5)*O44)+((5/24)*O45))/O44 -> 2.6359218 | Q44: =(C44*N45)+(P44*O44) -> 340629.28 | R44: =R45+Q44 -> 969519.36 | S44: =R44/N44 -> 13.134403 | T44: =S44-K44 -> 0.03440309
B45: 80 | C45: 5 | D45: ='Defunciones generales'!D95 -> 205 | E45: =Homicidios!D1235 -> 0 | F45: =(D45-E45)/D45 -> 1 | G45: =LT!H95 -> 60837 | H45: =1-LT!F95 -> 0.753915 | I45: =1-H45 -> 0.246085 | J45: =LT!G95 -> 2.5 | K45: =LT!L95 -> 10.18 | L45: =H45^F45 -> 0.753915 | M45: =1-L45 -> 0.246085 | N45: =N44*L44 -> 61782.232 | O45: =N45*M45 -> 15203.68 | P45: =C45+(F45*(I45/M45)*(J45-C45)) -> 2.5 | Q45: =(C45*N46)+(P45*O45) -> 270901.96 | R45: =R46+Q45 -> 628890.08 | S45: =R45/N45 -> 10.179142 | T45: =S45-K45 -> -0.00085840507
...
