Workbook

Sheet 2010H
A1: Colima: tabla de mortalidad masculina, 2010
A3: x(edad) | B3: n | C3: nNx | D3: nDx | E3: nmx | F3: nax | G3: nqx | H3: npx | I3: lx | J3: ndx | K3: nLx | L3: Tx | M3: ex
A4: 0 | B4: 1 | C4: 5805.255 | D4: 79.154649 | E4: 0.013635 | F4: =IF($E$4>=0.107,0.35,0.053+2.8*$E$4) -> 0.091177999 | G4: =(B4*E4)/(1+(B4-F4)*E4) -> 0.013468106 | H4: =1-G4 -> 0.98653189 | I4: 100000 | J4: =I4-I5 -> 1346.8106 | K4: =(B4+I5)+(F4*J4) -> 98776.989 | L4: =L5+K4 -> 1734929.4 | M4: =L4/I4 -> 17.349294
A5: 1 | B5: 4 | C5: 24229.116 | D5: 13.218513 | E5: 0.0005455632 | F5: =IF($E$4>=0.107,1.361,1.522-1.518*$E$4) -> 1.5013021 | G5: =(B5*E5)/(1+(B5-F5)*E5) -> 0.002179282 | H5: =1-G5 -> 0.99782072 | I5: =I4*H4 -> 98653.189 | J5: =I5-I6 -> 214.99312 | K5: =(B5+I6)+(F5*J5) -> 98764.966 | L5: =L6+K5 -> 1636152.4 | M5: =L5/I5 -> 16.584891
A6: 5 | B6: 5 | C6: 30708.301 | D6: 7.792236 | E6: 0.0002537501 | F6: =B6/2 -> 2.5 | G6: =(B6*E6)/(1+(B6-F6)*E6) -> 0.0012679461 | H6: =1-G6 -> 0.99873205 | I6: =I5*H5 -> 98438.196 | J6: =I6-I7 -> 124.81433 | K6: =(B6+I7)+(F6*J6) -> 98630.418 | L6: =L7+K6 -> 1537387.5 | M6: =L6/I6 -> 15.617794
A7: 10 | B7: 5 | C7: 31085.753 | D7: 5.760814 | E7: 0.0001853201 | F7: =B7/2 -> 2.5 | G7: =(B7*E7)/(1+(B7-F7)*E7) -> 0.0009261714 | H7: =1-G7 -> 0.99907383 | I7: =I6*H6 -> 98313.382 | J7: =I7-I8 -> 91.055043 | K7: =(B7+I8)+(F7*J7) -> 98454.965 | L7: =L8+K7 -> 1438757.1 | M7: =L7/I7 -> 14.634397
A8: 15 | B8: 5 | C8: 31929.628 | D8: 32.539257 | E8: 0.0010190929 | F8: =B8/2 -> 2.5 | G8: =(B8*E8)/(1+(B8-F8)*E8) -> 0.0050825156 | H8: =1-G8 -> 0.99491748 | I8: =I7*H7 -> 98222.327 | J8: =I8-I9 -> 499.21651 | K8: =(B8+I9)+(F8*J8) -> 98976.152 | L8: =L9+K8 -> 1340302.1 | M8: =L8/I8 -> 13.645595
A9: 20 | B9: 5 | C9: 29850.524 | D9: 45.415026 | E9: 0.0015214147 | F9: =B9/2 -> 2.5 | G9: =(B9*E9)/(1+(B9-F9)*E9) -> 0.0075782494 | H9: =1-G9 -> 0.99242175 | I9: =I8*H8 -> 97723.11 | J9: =I9-I10 -> 740.5701 | K9: =(B9+I10)+(F9*J9) -> 98838.966 | L9: =L10+K9 -> 1241325.9 | M9: =L9/I9 -> 12.702481
A10: 25 | B10: 5 | C10: 26319.462 | D10: 54.570811 | E10: 0.0020734015 | F10: =B10/2 -> 2.5 | G10: =(B10*E10)/(1+(B10-F10)*E10) -> 0.010313547 | H10: =1-G10 -> 0.98968645 | I10: =I9*H9 -> 96982.54 | J10: =I10-I11 -> 1000.234 | K10: =(B10+I11)+(F10*J10) -> 98487.891 | L10: =L11+K10 -> 1142487 | M10: =L10/I10 -> 11.780337
A11: 30 | B11: 5 | C11: 24899.129 | D11: 63.721834 | E11: 0.0025591994 | F11: =B11/2 -> 2.5 | G11: =(B11*E11)/(1+(B11-F11)*E11) -> 0.012714649 | H11: =1-G11 -> 0.98728535 | I11: =I10*H10 -> 95982.306 | J11: =I11-I12 -> 1220.3813 | K11: =(B11+I12)+(F11*J11) -> 97817.878 | L11: =L12+K11 -> 1043999.1 | M11: =L11/I11 -> 10.876995
A12: 35 | B12: 5 | C12: 24167.592 | D12: 84.050791 | E12: 0.0034778306 | F12: =B12/2 -> 2.5 | G12: =(B12*E12)/(1+(B12-F12)*E12) -> 0.017239265 | H12: =1-G12 -> 0.98276074 | I12: =I11*H11 -> 94761.925 | J12: =I12-I13 -> 1633.6259 | K12: =(B12+I13)+(F12*J12) -> 97217.364 | L12: =L13+K12 -> 946181.21 | M12: =L12/I12 -> 9.9848247
A13: 40 | B13: 5 | C13: 20357.604 | D13: 87.43634 | E13: 0.0042950211 | F13: =B13/2 -> 2.5 | G13: =(B13*E13)/(1+(B13-F13)*E13) -> 0.021246965 | H13: =1-G13 -> 0.97875303 | I13: =I12*H12 -> 93128.299 | J13: =I13-I14 -> 1978.6937 | K13: =(B13+I14)+(F13*J13) -> 96101.34 | L13: =L14+K13 -> 848963.84 | M13: =L13/I13 -> 9.1160673
A14: 45 | B14: 5 | C14: 17731.082 | D14: 95.247647 | E14: 0.0053717898 | F14: =B14/2 -> 2.5 | G14: =(B14*E14)/(1+(B14-F14)*E14) -> 0.026503027 | H14: =1-G14 -> 0.97349697 | I14: =I13*H13 -> 91149.605 | J14: =I14-I15 -> 2415.7405 | K14: =(B14+I15)+(F14*J14) -> 94778.216 | L14: =L15+K14 -> 752862.5 | M14: =L14/I14 -> 8.2596354
A15: 50 | B15: 5 | C15: 15443.718 | D15: 109.80148 | E15: 0.0071097828 | F15: =B15/2 -> 2.5 | G15: =(B15*E15)/(1+(B15-F15)*E15) -> 0.034928086 | H15: =1-G15 -> 0.96507191 | I15: =I14*H14 -> 88733.865 | J15: =I15-I16 -> 3099.3041 | K15: =(B15+I16)+(F15*J15) -> 93387.821 | L15: =L16+K15 -> 658084.29 | M15: =L15/I15 -> 7.4163826
A16: 55 | B16: 5 | C16: 11732.932 | D16: 121.3397 | E16: 0.010341805 | F16: =B16/2 -> 2.5 | G16: =(B16*E16)/(1+(B16-F16)*E16) -> 0.050405807 | H16: =1-G16 -> 0.94959419 | I16: =I15*H15 -> 85634.561 | J16: =I16-I17 -> 4316.4791 | K16: =(B16+I17)+(F16*J16) -> 92114.28 | L16: =L17+K16 -> 564696.47 | M16: =L16/I16 -> 6.5942589
A17: 60 | B17: 5 | C17: 9058.325 | D17: 150.13091 | E17: 0.016573805 | F17: =B17/2 -> 2.5 | G17: =(B17*E17)/(1+(B17-F17)*E17) -> 0.079571996 | H17: =1-G17 -> 0.920428 | I17: =I16*H16 -> 81318.082 | J17: =I17-I18 -> 6470.642 | K17: =(B17+I18)+(F17*J17) -> 91029.045 | L17: =L18+K17 -> 472582.19 | M17: =L17/I17 -> 5.8115265
... A21: 80 | B21: 5 | C21: 2077.07 | D21: 158.95005 | E21: 0.076526111 | F21: =B21/2 -> 2.5 | G21: =(B21*E21)/(1+(B21-F21)*E21) -> 0.32118328 | H21: =1-G21 -> 0.67881672 | I21: =I20*H20 -> 43031.953 | J21: =I21-I22 -> 13821.144 | K21: =(B21+I22)+(F21*J21) -> 63768.669 | L21: =L22+K21 -> 136800.69 | M21: =L21/I21 -> 3.1790491
A22: 85+ | B22: 5 | C22: 2203.458 | D22: 295.54094 | E22: 0.13412595 | F22: =B22/2 -> 2.5 | G22: =(B22*E22)/(1+(B22-F22)*E22) -> 0.50222594 | H22: =1-G22 -> 0.49777406 | I22: =I21*H21 -> 29210.809 | J22: =I22-I23 -> 29210.809 | K22: =(B22+I23)+(F22*J22) -> 73032.022 | L22: =L23+K22 -> 73032.022 | M22: =L22/I22 -> 2.5001712

Sheet 2010F
A1: Colima: tabla de mortalidad femenina, 2010
A3: x(edad) | B3: n | C3: nNx | D3: nDx | E3: nmx | F3: nax | G3: nqx | H3: npx | I3: lx | J3: ndx | K3: nLx | L3: Tx | M3: ex
A4: 0 | B4: 1 | C4: 5556.061 | D4: 65.976024 | E4: 0.011874603 | F4: =IF($E$4>=0.107,0.35,0.053+2.8*$E$4) -> 0.086248889 | G4: =(B4*E4)/(1+(B4-F4)*E4) -> 0.011747142 | H4: =1-G4 -> 0.98825286 | I4: 100000 | J4: =I4-I5 -> 1174.7142 | K4: =(B4+I5)+(F4*J4) -> 98927.604 | L4: =L5+K4 -> 1841568.6 | M4: =L4/I4 -> 18.415686
A5: 1 | B5: 4 | C5: 23369.41 | D5: 13.365414 | E5: 0.0005719192 | F5: =IF($E$4>=0.107,1.361,1.522-1.518*$E$4) -> 1.5039744 | G5: =(B5*E5)/(1+(B5-F5)*E5) -> 0.0022844157 | H5: =1-G5 -> 0.99771558 | I5: =I4*H4 -> 98825.286 | J5: =I5-I6 -> 225.75804 | K5: =(B5+I6)+(F5*J5) -> 98943.062 | L5: =L6+K5 -> 1742641 | M5: =L5/I5 -> 17.633554
A6: 5 | B6: 5 | C6: 29890.988 | D6: 6.348691 | E6: 0.0002123948 | F6: =B6/2 -> 2.5 | G6: =(B6*E6)/(1+(B6-F6)*E6) -> 0.0010614104 | H6: =1-G6 -> 0.99893859 | I6: =I5*H5 -> 98599.528 | J6: =I6-I7 -> 104.65456 | K6: =(B6+I7)+(F6*J6) -> 98761.51 | L6: =L7+K6 -> 1643698 | M6: =L6/I6 -> 16.670445
A7: 10 | B7: 5 | C7: 29115.268 | D7: 6.011409 | E7: 0.0002064693 | F7: =B7/2 -> 2.5 | G7: =(B7*E7)/(1+(B7-F7)*E7) -> 0.0010318139 | H7: =1-G7 -> 0.99896819 | I7: =I6*H6 -> 98494.873 | J7: =I7-I8 -> 101.62838 | K7: =(B7+I8)+(F7*J7) -> 98652.316 | L7: =L8+K7 -> 1544936.5 | M7: =L7/I7 -> 15.685451
A8: 15 | B8: 5 | C8: 31149.59 | D8: 11.026908 | E8: 0.0003539985 | F8: =B8/2 -> 2.5 | G8: =(B8*E8)/(1+(B8-F8)*E8) -> 0.0017684274 | H8: =1-G8 -> 0.99823157 | I8: =I7*H7 -> 98393.245 | J8: =I8-I9 -> 174.00131 | K8: =(B8+I9)+(F8*J8) -> 98659.247 | L8: =L9+K8 -> 1446284.2 | M8: =L8/I8 -> 14.699019
A9: 20 | B9: 5 | C9: 30950.009 | D9: 13.699176 | E9: 0.0004426227 | F9: =B9/2 -> 2.5 | G9: =(B9*E9)/(1+(B9-F9)*E9) -> 0.0022106673 | H9: =1-G9 -> 0.99778933 | I9: =I8*H8 -> 98219.244 | J9: =I9-I10 -> 217.13007 | K9: =(B9+I10)+(F9*J9) -> 98549.939 | L9: =L10+K9 -> 1347624.9 | M9: =L9/I9 -> 13.720579
A10: 25 | B10: 5 | C10: 27474.145 | D10: 19.711333 | E10: 0.0007174503 | F10: =B10/2 -> 2.5 | G10: =(B10*E10)/(1+(B10-F10)*E10) -> 0.0035808288 | H10: =1-G10 -> 0.99641917 | I10: =I9*H9 -> 98002.113 | J10: =I10-I11 -> 350.92879 | K10: =(B10+I11)+(F10*J10) -> 98533.507 | L10: =L11+K10 -> 1249075 | M10: =L10/I10 -> 12.745388
A11: 30 | B11: 5 | C11: 26251.414 | D11: 26.054908 | E11: 0.0009925144 | F11: =B11/2 -> 2.5 | G11: =(B11*E11)/(1+(B11-F11)*E11) -> 0.0049502889 | H11: =1-G11 -> 0.99504971 | I11: =I10*H10 -> 97651.185 | J11: =I11-I12 -> 483.40158 | K11: =(B11+I12)+(F11*J11) -> 98381.287 | L11: =L12+K11 -> 1150541.5 | M11: =L11/I11 -> 11.782156
A12: 35 | B12: 5 | C12: 25302.446 | D12: 21.04539 | E12: 0.0008317532 | F12: =B12/2 -> 2.5 | G12: =(B12*E12)/(1+(B12-F12)*E12) -> 0.0041501363 | H12: =1-G12 -> 0.99584986 | I12: =I11*H11 -> 97167.783 | J12: =I12-I13 -> 403.25954 | K12: =(B12+I13)+(F12*J12) -> 97777.672 | L12: =L13+K12 -> 1052160.2 | M12: =L12/I12 -> 10.828282
A13: 40 | B13: 5 | C13: 21598.026 | D13: 30.737314 | E13: 0.0014231538 | F13: =B13/2 -> 2.5 | G13: =(B13*E13)/(1+(B13-F13)*E13) -> 0.0070905417 | H13: =1-G13 -> 0.99290946 | I13: =I12*H12 -> 96764.524 | J13: =I13-I14 -> 686.11289 | K13: =(B13+I14)+(F13*J13) -> 97798.693 | L13: =L14+K13 -> 954382.5 | M13: =L13/I13 -> 9.8629381
A14: 45 | B14: 5 | C14: 18538.414 | D14: 43.09523 | E14: 0.0023246449 | F14: =B14/2 -> 2.5 | G14: =(B14*E14)/(1+(B14-F14)*E14) -> 0.011556065 | H14: =1-G14 -> 0.98844393 | I14: =I13*H13 -> 96078.411 | J14: =I14-I15 -> 1110.2884 | K14: =(B14+I15)+(F14*J14) -> 97748.843 | L14: =L15+K14 -> 856583.81 | M14: =L14/I14 -> 8.9154661
A15: 50 | B15: 5 | C15: 15869.633 | D15: 50.451303 | E15: 0.0031791096 | F15: =B15/2 -> 2.5 | G15: =(B15*E15)/(1+(B15-F15)*E15) -> 0.01577021 | H15: =1-G15 -> 0.98422979 | I15: =I14*H14 -> 94968.122 | J15: =I15-I16 -> 1497.6672 | K15: =(B15+I16)+(F15*J15) -> 97219.623 | L15: =L16+K15 -> 758834.97 | M15: =L15/I15 -> 7.9904177
A16: 55 | B16: 5 | C16: 11872.102 | D16: 72.496596 | E16: 0.0061064669 | F16: =B16/2 -> 2.5 | G16: =(B16*E16)/(1+(B16-F16)*E16) -> 0.030073232 | H16: =1-G16 -> 0.96992677 | I16: =I15*H15 -> 93470.455 | J16: =I16-I17 -> 2810.9586 | K16: =(B16+I17)+(F16*J16) -> 97691.893 | L16: =L17+K16 -> 661615.34 | M16: =L16/I16 -> 7.0783366
A17: 60 | B17: 5 | C17: 9539.393 | D17: 87.188178 | E17: 0.0091398039 | F17: =B17/2 -> 2.5 | G17: =(B17*E17)/(1+(B17-F17)*E17) -> 0.044678146 | H17: =1-G17 -> 0.95532185 | I17: =I16*H16 -> 90659.496 | J17: =I17-I18 -> 4050.4982 | K17: =(B17+I18)+(F17*J17) -> 96740.244 | L17: =L18+K17 -> 563923.45 | M17: =L17/I17 -> 6.2202358
... A21: 80 | B21: 5 | C21: 2547.496 | D21: 148.66619 | E21: 0.058357772 | F21: =B21/2 -> 2.5 | G21: =(B21*E21)/(1+(B21-F21)*E21) -> 0.25463852 | H21: =1-G21 -> 0.74536148 | I21: =I20*H20 -> 57243.623 | J21: =I21-I22 -> 14576.431 | K21: =(B21+I22)+(F21*J21) -> 79113.27 | L21: =L22+K21 -> 185786.25 | M21: =L21/I21 -> 3.2455362
A22: 85+ | B22: 5 | C22: 2644.033 | D22: 347.44682 | E22: 0.13140791 | F22: =B22/2 -> 2.5 | G22: =(B22*E22)/(1+(B22-F22)*E22) -> 0.49456513 | H22: =1-G22 -> 0.50543487 | I22: =I21*H21 -> 42667.192 | J22: =I22-I23 -> 42667.192 | K22: =(B22+I23)+(F22*J22) -> 106672.98 | L22: =L23+K22 -> 106672.98 | M22: =L22/I22 -> 2.5001172

Sheet 2019H
A1: Colima: tabla de mortalidad masculina, 2019
A3: x(edad) | B3: n | C3: nNx | D3: nDx | E3: nmx | F3: nax | G3: nqx | H3: npx | I3: lx | J3: ndx | K3: nLx | L3: Tx | M3: ex
A4: 0 | B4: 1 | C4: 4797.612 | D4: 46.083333 | E4: 0.0096054723 | F4: =IF($E$4>=0.107,0.35,0.053+2.8*$E$4) -> 0.079895322 | G4: =(B4*E4)/(1+(B4-F4)*E4) -> 0.0095213225 | H4: =1-G4 -> 0.99047868 | I4: 100000 | J4: =I4-I5 -> 952.13225 | K4: =(B4+I5)+(F4*J4) -> 99124.939 | L4: =L5+K4 -> 1694223.4 | M4: =L4/I4 -> 16.942234
A5: 1 | B5: 4 | C5: 22039.426 | D5: 11.019928 | E5: 0.0005000097 | F5: =IF($E$4>=0.107,1.361,1.522-1.518*$E$4) -> 1.5074189 | G5: =(B5*E5)/(1+(B5-F5)*E5) -> 0.0019975492 | H5: =1-G5 -> 0.99800245 | I5: =I4*H4 -> 99047.868 | J5: =I5-I6 -> 197.85299 | K5: =(B5+I6)+(F5*J5) -> 99152.262 | L5: =L6+K5 -> 1595098.5 | M5: =L5/I5 -> 16.104319
A6: 5 | B6: 5 | C6: 30727.577 | D6: 6.01087 | E6: 0.0001956181 | F6: =B6/2 -> 2.5 | G6: =(B6*E6)/(1+(B6-F6)*E6) -> 0.0009776124 | H6: =1-G6 -> 0.99902239 | I6: =I5*H5 -> 98850.015 | J6: =I6-I7 -> 96.637 | K6: =(B6+I7)+(F6*J6) -> 98999.97 | L6: =L7+K6 -> 1495946.2 | M6: =L6/I6 -> 15.133495
A7: 10 | B7: 5 | C7: 31039.515 | D7: 7.012681 | E7: 0.0002259275 | F7: =B7/2 -> 2.5 | G7: =(B7*E7)/(1+(B7-F7)*E7) -> 0.0011289998 | H7: =1-G7 -> 0.998871 | I7: =I6*H6 -> 98753.378 | J7: =I7-I8 -> 111.49255 | K7: =(B7+I8)+(F7*J7) -> 98925.617 | L7: =L8+K7 -> 1396946.2 | M7: =L7/I7 -> 14.145807
A8: 15 | B8: 5 | C8: 30834.02 | D8: 56.101449 | E8: 0.0018194659 | F8: =B8/2 -> 2.5 | G8: =(B8*E8)/(1+(B8-F8)*E8) -> 0.0090561362 | H8: =1-G8 -> 0.99094386 | I8: =I7*H7 -> 98641.885 | J8: =I8-I9 -> 893.31434 | K8: =(B8+I9)+(F8*J8) -> 99986.857 | L8: =L9+K8 -> 1298020.6 | M8: =L8/I8 -> 13.15892
A9: 20 | B9: 5 | C9: 29726.964 | D9: 124.22464 | E9: 0.0041788538 | F9: =B9/2 -> 2.5 | G9: =(B9*E9)/(1+(B9-F9)*E9) -> 0.020678241 | H9: =1-G9 -> 0.97932176 | I9: =I8*H8 -> 97748.571 | J9: =I9-I10 -> 2021.2685 | K9: =(B9+I10)+(F9*J9) -> 100785.47 | L9: =L10+K9 -> 1198033.8 | M9: =L9/I9 -> 12.256279
A10: 25 | B10: 5 | C10: 28485.206 | D10: 146.26449 | E10: 0.0051347528 | F10: =B10/2 -> 2.5 | G10: =(B10*E10)/(1+(B10-F10)*E10) -> 0.02534837 | H10: =1-G10 -> 0.97465163 | I10: =I9*H9 -> 95727.302 | J10: =I10-I11 -> 2426.5311 | K10: =(B10+I11)+(F10*J10) -> 99372.099 | L10: =L11+K10 -> 1097248.3 | M10: =L10/I10 -> 11.462229
A11: 30 | B11: 5 | C11: 27545.159 | D11: 139.25181 | E11: 0.0050554005 | F11: =B11/2 -> 2.5 | G11: =(B11*E11)/(1+(B11-F11)*E11) -> 0.024961526 | H11: =1-G11 -> 0.97503847 | I11: =I10*H10 -> 93300.771 | J11: =I11-I12 -> 2328.9296 | K11: =(B11+I12)+(F11*J11) -> 96799.166 | L11: =L12+K11 -> 997876.2 | M11: =L11/I11 -> 10.695262
A12: 35 | B12: 5 | C12: 26513.843 | D12: 126.22826 | E12: 0.0047608437 | F12: =B12/2 -> 2.5 | G12: =(B12*E12)/(1+(B12-F12)*E12) -> 0.023524231 | H12: =1-G12 -> 0.97647577 | I12: =I11*H11 -> 90971.842 | J12: =I12-I13 -> 2140.0426 | K12: =(B12+I13)+(F12*J12) -> 94186.906 | L12: =L13+K12 -> 901077.04 | M12: =L12/I12 -> 9.9050104
A13: 40 | B13: 5 | C13: 24496.871 | D13: 154.27899 | E13: 0.0062979058 | F13: =B13/2 -> 2.5 | G13: =(B13*E13)/(1+(B13-F13)*E13) -> 0.031001419 | H13: =1-G13 -> 0.96899858 | I13: =I12*H12 -> 88831.799 | J13: =I13-I14 -> 2753.9118 | K13: =(B13+I14)+(F13*J13) -> 92967.667 | L13: =L14+K13 -> 806890.13 | M13: =L13/I13 -> 9.0833479
A14: 45 | B14: 5 | C14: 22761.843 | D14: 152.27536 | E14: 0.00668994 | F14: =B14/2 -> 2.5 | G14: =(B14*E14)/(1+(B14-F14)*E14) -> 0.032899461 | H14: =1-G14 -> 0.96710054 | I14: =I13*H13 -> 86077.887 | J14: =I14-I15 -> 2831.9161 | K14: =(B14+I15)+(F14*J14) -> 90330.761 | L14: =L15+K14 -> 713922.47 | M14: =L14/I14 -> 8.2939125
A15: 50 | B15: 5 | C15: 19712.389 | D15: 162.29348 | E15: 0.0082330699 | F15: =B15/2 -> 2.5 | G15: =(B15*E15)/(1+(B15-F15)*E15) -> 0.040335144 | H15: =1-G15 -> 0.95966486 | I15: =I14*H14 -> 83245.971 | J15: =I15-I16 -> 3357.7383 | K15: =(B15+I16)+(F15*J15) -> 88287.579 | L15: =L16+K15 -> 623591.7 | M15: =L15/I15 -> 7.4909536
A16: 55 | B16: 5 | C16: 16449.264 | D16: 202.36594 | E16: 0.012302431 | F16: =B16/2 -> 2.5 | G16: =(B16*E16)/(1+(B16-F16)*E16) -> 0.059676733 | H16: =1-G16 -> 0.94032327 | I16: =I15*H15 -> 79888.233 | J16: =I16-I17 -> 4767.4688 | K16: =(B16+I17)+(F16*J16) -> 87044.436 | L16: =L17+K16 -> 535304.13 | M16: =L16/I16 -> 6.700663
A17: 60 | B17: 5 | C17: 14025.565 | D17: 234.42391 | E17: 0.016714044 | F17: =B17/2 -> 2.5 | G17: =(B17*E17)/(1+(B17-F17)*E17) -> 0.08021829 | H17: =1-G17 -> 0.91978171 | I17: =I16*H16 -> 75120.764 | J17: =I17-I18 -> 6026.0593 | K17: =(B17+I18)+(F17*J17) -> 84164.853 | L17: =L18+K17 -> 448259.69 | M17: =L17/I17 -> 5.9671876
... A21: 80 | B21: 5 | C21: 3021.729 | D21: 186.33696 | E21: 0.061665684 | F21: =B21/2 -> 2.5 | G21: =(B21*E21)/(1+(B21-F21)*E21) -> 0.26714432 | H21: =1-G21 -> 0.73285568 | I21: =I20*H20 -> 42742.465 | J21: =I21-I22 -> 11418.407 | K21: =(B21+I22)+(F21*J21) -> 59875.075 | L21: =L22+K21 -> 138190.22 | M21: =L21/I21 -> 3.2330896
A22: 85+ | B22: 5 | C22: 2488.095 | D22: 361.65399 | E22: 0.14535377 | F22: =B22/2 -> 2.5 | G22: =(B22*E22)/(1+(B22-F22)*E22) -> 0.5330623 | H22: =1-G22 -> 0.4669377 | I22: =I21*H21 -> 31324.058 | J22: =I22-I23 -> 31324.058 | K22: =(B22+I23)+(F22*J22) -> 78315.144 | L22: =L23+K22 -> 78315.144 | M22: =L22/I22 -> 2.5001596

Sheet 2019F
A1: Colima: tabla de mortalidad femenina, 2019
A3: x(edad) | B3: n | C3: nNx | D3: nDx | E3: nmx | F3: nax | G3: nqx | H3: npx | I3: lx | J3: ndx | K3: nLx | L3: Tx | M3: ex
A4: 0 | B4: 1 | C4: 4636.109 | D4: 34.076233 | E4: 0.0073501791 | F4: =IF($E$4>=0.107,0.35,0.053+2.8*$E$4) -> 0.073580501 | G4: =(B4*E4)/(1+(B4-F4)*E4) -> 0.0073004677 | H4: =1-G4 -> 0.99269953 | I4: 100000 | J4: =I4-I5 -> 730.04677 | K4: =(B4+I5)+(F4*J4) -> 99324.67 | L4: =L5+K4 -> 1847863.5 | M4: =L4/I4 -> 18.478635
A5: 1 | B5: 4 | C5: 21423.149 | D5: 17.038117 | E5: 0.0007953133 | F5: =IF($E$4>=0.107,1.361,1.522-1.518*$E$4) -> 1.5108424 | G5: =(B5*E5)/(1+(B5-F5)*E5) -> 0.0031749678 | H5: =1-G5 -> 0.99682503 | I5: =I4*H4 -> 99269.953 | J5: =I5-I6 -> 315.17891 | K5: =(B5+I6)+(F5*J5) -> 99434.96 | L5: =L6+K5 -> 1748538.8 | M5: =L5/I5 -> 17.613979
A6: 5 | B6: 5 | C6: 29510.485 | D6: 8.017937 | E6: 0.0002716979 | F6: =B6/2 -> 2.5 | G6: =(B6*E6)/(1+(B6-F6)*E6) -> 0.0013575674 | H6: =1-G6 -> 0.99864243 | I6: =I5*H5 -> 98954.774 | J6: =I6-I7 -> 134.33777 | K6: =(B6+I7)+(F6*J6) -> 99161.281 | L6: =L7+K6 -> 1649103.9 | M6: =L6/I6 -> 16.665228
A7: 10 | B7: 5 | C7: 29868.597 | D7: 5.011211 | E7: 0.0001677752 | F7: =B7/2 -> 2.5 | G7: =(B7*E7)/(1+(B7-F7)*E7) -> 0.00083852429 | H7: =1-G7 -> 0.99916148 | I7: =I6*H6 -> 98820.437 | J7: =I7-I8 -> 82.863336 | K7: =(B7+I8)+(F7*J7) -> 98949.732 | L7: =L8+K7 -> 1549942.6 | M7: =L7/I7 -> 15.684434
A8: 15 | B8: 5 | C8: 30152.048 | D8: 14.03139 | E8: 0.0004653545 | F8: =B8/2 -> 2.5 | G8: =(B8*E8)/(1+(B8-F8)*E8) -> 0.0023240687 | H8: =1-G8 -> 0.99767593 | I8: =I7*H7 -> 98737.573 | J8: =I8-I9 -> 229.4729 | K8: =(B8+I9)+(F8*J8) -> 99086.783 | L8: =L9+K8 -> 1450992.9 | M8: =L8/I8 -> 14.695448
A9: 20 | B9: 5 | C9: 29867.644 | D9: 33.073991 | E9: 0.0011073519 | F9: =B9/2 -> 2.5 | G9: =(B9*E9)/(1+(B9-F9)*E9) -> 0.005521474 | H9: =1-G9 -> 0.99447853 | I9: =I8*H8 -> 98508.1 | J9: =I9-I10 -> 543.90991 | K9: =(B9+I10)+(F9*J9) -> 99328.965 | L9: =L10+K9 -> 1351906.1 | M9: =L9/I9 -> 13.723806
A10: 25 | B10: 5 | C10: 29375.375 | D10: 36.080717 | E10: 0.001228264 | F10: =B10/2 -> 2.5 | G10: =(B10*E10)/(1+(B10-F10)*E10) -> 0.0061225198 | H10: =1-G10 -> 0.99387748 | I10: =I9*H9 -> 97964.19 | J10: =I10-I11 -> 599.7877 | K10: =(B10+I11)+(F10*J10) -> 98868.872 | L10: =L11+K10 -> 1252577.1 | M10: =L10/I10 -> 12.786071
A11: 30 | B11: 5 | C11: 29552.541 | D11: 30.067265 | E11: 0.0010174172 | F11: =B11/2 -> 2.5 | G11: =(B11*E11)/(1+(B11-F11)*E11) -> 0.0050741796 | H11: =1-G11 -> 0.99492582 | I11: =I10*H10 -> 97364.403 | J11: =I11-I12 -> 494.04447 | K11: =(B11+I12)+(F11*J11) -> 98110.469 | L11: =L12+K11 -> 1153708.3 | M11: =L11/I11 -> 11.849385
A12: 35 | B12: 5 | C12: 27801.079 | D12: 31.069507 | E12: 0.0011175648 | F12: =B12/2 -> 2.5 | G12: =(B12*E12)/(1+(B12-F12)*E12) -> 0.0055722556 | H12: =1-G12 -> 0.99442774 | I12: =I11*H11 -> 96870.358 | J12: =I12-I13 -> 539.7864 | K12: =(B12+I13)+(F12*J12) -> 97685.038 | L12: =L13+K12 -> 1055597.8 | M12: =L12/I12 -> 10.897015
A13: 40 | B13: 5 | C13: 26076.791 | D13: 44.098655 | E13: 0.0016911074 | F13: =B13/2 -> 2.5 | G13: =(B13*E13)/(1+(B13-F13)*E13) -> 0.0084199394 | H13: =1-G13 -> 0.99158006 | I13: =I12*H12 -> 96330.572 | J13: =I13-I14 -> 811.09758 | K13: =(B13+I14)+(F13*J13) -> 97552.218 | L13: =L14+K13 -> 957912.75 | M13: =L13/I13 -> 9.944016
A14: 45 | B14: 5 | C14: 23600.846 | D14: 74.165919 | E14: 0.003142511 | F14: =B14/2 -> 2.5 | G14: =(B14*E14)/(1+(B14-F14)*E14) -> 0.015590075 | H14: =1-G14 -> 0.98440992 | I14: =I13*H13 -> 95519.474 | J14: =I14-I15 -> 1489.1558 | K14: =(B14+I15)+(F14*J14) -> 97758.208 | L14: =L15+K14 -> 860360.53 | M14: =L14/I14 -> 9.007174
A15: 50 | B15: 5 | C15: 21088.062 | D15: 80.179372 | E15: 0.0038021215 | F15: =B15/2 -> 2.5 | G15: =(B15*E15)/(1+(B15-F15)*E15) -> 0.018831607 | H15: =1-G15 -> 0.98116839 | I15: =I14*H14 -> 94030.318 | J15: =I15-I16 -> 1770.742 | K15: =(B15+I16)+(F15*J15) -> 96691.432 | L15: =L16+K15 -> 762602.32 | M15: =L15/I15 -> 8.1101748
A16: 55 | B16: 5 | C16: 17487.233 | D16: 92.206278 | E16: 0.0052727769 | F16: =B16/2 -> 2.5 | G16: =(B16*E16)/(1+(B16-F16)*E16) -> 0.026020879 | H16: =1-G16 -> 0.97397912 | I16: =I15*H15 -> 92259.576 | J16: =I16-I17 -> 2400.6753 | K16: =(B16+I17)+(F16*J16) -> 95865.589 | L16: =L17+K16 -> 665910.89 | M16: =L16/I16 -> 7.2177969
A17: 60 | B17: 5 | C17: 14841.869 | D17: 133.29821 | E17: 0.0089812276 | F17: =B17/2 -> 2.5 | G17: =(B17*E17)/(1+(B17-F17)*E17) -> 0.043919999 | H17: =1-G17 -> 0.95608 | I17: =I16*H16 -> 89858.901 | J17: =I17-I18 -> 3946.6029 | K17: =(B17+I18)+(F17*J17) -> 95783.805 | L17: =L18+K17 -> 570045.3 | M17: =L17/I17 -> 6.3437822
... A21: 80 | B21: 5 | C21: 3660.916 | D21: 205.45964 | E21: 0.056122465 | F21: =B21/2 -> 2.5 | G21: =(B21*E21)/(1+(B21-F21)*E21) -> 0.24608507 | H21: =1-G21 -> 0.75391493 | I21: =I20*H20 -> 60837.395 | J21: =I21-I22 -> 14971.175 | K21: =(B21+I22)+(F21*J21) -> 83299.157 | L21: =L22+K21 -> 197969.71 | M21: =L21/I21 -> 3.2540793
A22: 85+ | B22: 5 | C22: 3381.581 | D22: 439.98431 | E22: 0.13011203 | F22: =B22/2 -> 2.5 | G22: =(B22*E22)/(1+(B22-F22)*E22) -> 0.49088502 | H22: =1-G22 -> 0.50911498 | I22: =I21*H21 -> 45866.22 | J22: =I22-I23 -> 45866.22 | K22: =(B22+I23)+(F22*J22) -> 114670.55 | L22: =L23+K22 -> 114670.55 | M22: =L22/I22 -> 2.500109

Sheet 2021H
A1: Colima: tabla de mortalidad masculina, 2021
A3: x(edad) | B3: n | C3: nNx | D3: nDx | E3: nmx | F3: nax | G3: nqx | H3: npx | I3: lx | J3: ndx | K3: nLx | L3: Tx | M3: ex
A4: 0 | B4: 1 | C4: 4598.604 | D4: 49.688097 | E4: 0.010805039 | F4: =IF($E$4>=0.107,0.35,0.053+2.8*$E$4) -> 0.083254109 | G4: =(B4*E4)/(1+(B4-F4)*E4) -> 0.01069906 | H4: =1-G4 -> 0.98930094 | I4: 100000 | J4: =I4-I5 -> 1069.906 | K4: =(B4+I5)+(F4*J4) -> 99020.168 | L4: =L5+K4 -> 1606974.1 | M4: =L4/I4 -> 16.069741
A5: 1 | B5: 4 | C5: 21580.358 | D5: 11.023242 | E5: 0.0005107998 | F5: =IF($E$4>=0.107,1.361,1.522-1.518*$E$4) -> 1.505598 | G5: =(B5*E5)/(1+(B5-F5)*E5) -> 0.0020405992 | H5: =1-G5 -> 0.9979594 | I5: =I4*H4 -> 98930.094 | J5: =I5-I6 -> 201.87667 | K5: =(B5+I6)+(F5*J5) -> 99036.162 | L5: =L6+K5 -> 1507953.9 | M5: =L5/I5 -> 15.242621
A6: 5 | B6: 5 | C6: 30731.862 | D6: 9.019016 | E6: 0.0002934744 | F6: =B6/2 -> 2.5 | G6: =(B6*E6)/(1+(B6-F6)*E6) -> 0.0014662962 | H6: =1-G6 -> 0.9985337 | I6: =I5*H5 -> 98728.217 | J6: =I6-I7 -> 144.76481 | K6: =(B6+I7)+(F6*J6) -> 98950.365 | L6: =L7+K6 -> 1408917.8 | M6: =L6/I6 -> 14.27067
A7: 10 | B7: 5 | C7: 31029.25 | D7: 8.016903 | E7: 0.000258366 | F7: =B7/2 -> 2.5 | G7: =(B7*E7)/(1+(B7-F7)*E7) -> 0.0012909961 | H7: =1-G7 -> 0.998709 | I7: =I6*H6 -> 98583.453 | J7: =I7-I8 -> 127.27086 | K7: =(B7+I8)+(F7*J7) -> 98779.359 | L7: =L8+K7 -> 1309967.4 | M7: =L7/I7 -> 13.287904
A8: 15 | B8: 5 | C8: 30595.703 | D8: 50.105644 | E8: 0.0016376693 | F8: =B8/2 -> 2.5 | G8: =(B8*E8)/(1+(B8-F8)*E8) -> 0.0081549587 | H8: =1-G8 -> 0.99184504 | I8: =I7*H7 -> 98456.182 | J8: =I8-I9 -> 802.90609 | K8: =(B8+I9)+(F8*J8) -> 99665.541 | L8: =L9+K8 -> 1211188.1 | M8: =L8/I8 -> 12.301798
A9: 20 | B9: 5 | C9: 29699.576 | D9: 123.25988 | E9: 0.0041502237 | F9: =B9/2 -> 2.5 | G9: =(B9*E9)/(1+(B9-F9)*E9) -> 0.020538025 | H9: =1-G9 -> 0.97946197 | I9: =I8*H8 -> 97653.276 | J9: =I9-I10 -> 2005.6054 | K9: =(B9+I10)+(F9*J9) -> 100666.68 | L9: =L10+K9 -> 1111522.5 | M9: =L9/I9 -> 11.382337
A10: 25 | B10: 5 | C10: 28990.186 | D10: 158.33383 | E10: 0.0054616357 | F10: =B10/2 -> 2.5 | G10: =(B10*E10)/(1+(B10-F10)*E10) -> 0.026940333 | H10: =1-G10 -> 0.97305967 | I10: =I9*H9 -> 95647.67 | J10: =I10-I11 -> 2576.7801 | K10: =(B10+I11)+(F10*J10) -> 99517.84 | L10: =L11+K10 -> 1010855.8 | M10: =L10/I10 -> 10.568536
A11: 30 | B11: 5 | C11: 28170.348 | D11: 155.3275 | E11: 0.0055138651 | F11: =B11/2 -> 2.5 | G11: =(B11*E11)/(1+(B11-F11)*E11) -> 0.027194459 | H11: =1-G11 -> 0.97280554 | I11: =I10*H10 -> 93070.89 | J11: =I11-I12 -> 2531.0125 | K11: =(B11+I12)+(F11*J11) -> 96872.409 | L11: =L12+K11 -> 911337.99 | M11: =L11/I11 -> 9.7918693
A12: 35 | B12: 5 | C12: 27065.418 | D12: 187.39511 | E12: 0.006923784 | F12: =B12/2 -> 2.5 | G12: =(B12*E12)/(1+(B12-F12)*E12) -> 0.034029881 | H12: =1-G12 -> 0.96597012 | I12: =I11*H11 -> 90539.878 | J12: =I12-I13 -> 3081.0613 | K12: =(B12+I13)+(F12*J12) -> 95166.47 | L12: =L13+K12 -> 814465.58 | M12: =L12/I12 -> 8.9956559
A13: 40 | B13: 5 | C13: 25525.468 | D13: 200.42258 | E13: 0.0078518669 | F13: =B13/2 -> 2.5 | G13: =(B13*E13)/(1+(B13-F13)*E13) -> 0.038503523 | H13: =1-G13 -> 0.96149648 | I13: =I12*H12 -> 87458.816 | J13: =I13-I14 -> 3367.4726 | K13: =(B13+I14)+(F13*J13) -> 92515.025 | L13: =L14+K13 -> 719299.11 | M13: =L13/I13 -> 8.2244323
A14: 45 | B14: 5 | C14: 24060.926 | D14: 205.43314 | E14: 0.0085380395 | F14: =B14/2 -> 2.5 | G14: =(B14*E14)/(1+(B14-F14)*E14) -> 0.041798015 | H14: =1-G14 -> 0.95820199 | I14: =I13*H13 -> 84091.344 | J14: =I14-I15 -> 3514.8512 | K14: =(B14+I15)+(F14*J14) -> 89368.621 | L14: =L15+K14 -> 626784.09 | M14: =L14/I14 -> 7.4536101
A15: 50 | B15: 5 | C15: 20810.956 | D15: 277.58527 | E15: 0.01333842 | F15: =B15/2 -> 2.5 | G15: =(B15*E15)/(1+(B15-F15)*E15) -> 0.064539948 | H15: =1-G15 -> 0.93546005 | I15: =I14*H14 -> 80576.493 | J15: =I15-I16 -> 5200.4026 | K15: =(B15+I16)+(F15*J15) -> 88382.096 | L15: =L16+K15 -> 537415.47 | M15: =L15/I15 -> 6.6696309
A16: 55 | B16: 5 | C16: 17731.903 | D16: 315.66556 | E16: 0.017802125 | F16: =B16/2 -> 2.5 | G16: =(B16*E16)/(1+(B16-F16)*E16) -> 0.085217973 | H16: =1-G16 -> 0.91478203 | I16: =I15*H15 -> 75376.09 | J16: =I16-I17 -> 6423.3976 | K16: =(B16+I17)+(F16*J16) -> 85016.186 | L16: =L17+K16 -> 449033.37 | M16: =L16/I16 -> 5.9572388
A17: 60 | B17: 5 | C17: 15456.61 | D17: 389.82191 | E17: 0.025220402 | F17: =B17/2 -> 2.5 | G17: =(B17*E17)/(1+(B17-F17)*E17) -> 0.11862273 | H17: =1-G17 -> 0.88137727 | I17: =I16*H16 -> 68952.692 | J17: =I17-I18 -> 8179.3564 | K17: =(B17+I18)+(F17*J17) -> 81226.727 | L17: =L18+K17 -> 364017.18 | M17: =L17/I17 -> 5.2792309
... A21: 80 | B21: 5 | C21: 3284.235 | D21: 358.75641 | E21: 0.10923592 | F21: =B21/2 -> 2.5 | G21: =(B21*E21)/(1+(B21-F21)*E21) -> 0.42901891 | H21: =1-G21 -> 0.57098109 | I21: =I20*H20 -> 26840.139 | J21: =I21-I22 -> 11514.927 | K21: =(B21+I22)+(F21*J21) -> 44117.529 | L21: =L22+K21 -> 82435.558 | M21: =L21/I21 -> 3.0713537
A22: 85+ | B22: 5 | C22: 2556.183 | D22: 521.0987 | E22: 0.20385816 | F22: =B22/2 -> 2.5 | G22: =(B22*E22)/(1+(B22-F22)*E22) -> 0.67518558 | H22: =1-G22 -> 0.32481442 | I22: =I21*H21 -> 15325.212 | J22: =I22-I23 -> 15325.212 | K22: =(B22+I23)+(F22*J22) -> 38318.029 | L22: =L23+K22 -> 38318.029 | M22: =L22/I22 -> 2.5003263

Sheet 2021F
A1: Colima: tabla de mortalidad femenina, 2021
A3: x(edad) | B3: n | C3: nNx | D3: nDx | E3: nmx | F3: nax | G3: nqx | H3: npx | I3: lx | J3: ndx | K3: nLx | L3: Tx | M3: ex
A4: 0 | B4: 1 | C4: 4453.321 | D4: 35.416667 | E4: 0.007952866 | F4: =IF($E$4>=0.107,0.35,0.053+2.8*$E$4) -> 0.075268025 | G4: =(B4*E4)/(1+(B4-F4)*E4) -> 0.0078948055 | H4: =1-G4 -> 0.99210519 | I4: 100000 | J4: =I4-I5 -> 789.48055 | K4: =(B4+I5)+(F4*J4) -> 99270.942 | L4: =L5+K4 -> 1776019.4 | M4: =L4/I4 -> 17.760194
A5: 1 | B5: 4 | C5: 21013.153 | D5: 5 | E5: 0.0002379462 | F5: =IF($E$4>=0.107,1.361,1.522-1.518*$E$4) -> 1.5099275 | G5: =(B5*E5)/(1+(B5-F5)*E5) -> 0.0009512212 | H5: =1-G5 -> 0.99904878 | I5: =I4*H4 -> 99210.519 | J5: =I5-I6 -> 94.371149 | K5: =(B5+I6)+(F5*J5) -> 99262.642 | L5: =L6+K5 -> 1676748.4 | M5: =L5/I5 -> 16.900914
A6: 5 | B6: 5 | C6: 29426.589 | D6: 10 | E6: 0.0003398287 | F6: =B6/2 -> 2.5 | G6: =(B6*E6)/(1+(B6-F6)*E6) -> 0.0016977012 | H6: =1-G6 -> 0.9983023 | I6: =I5*H5 -> 99116.148 | J6: =I6-I7 -> 168.2696 | K6: =(B6+I7)+(F6*J6) -> 99373.553 | L6: =L7+K6 -> 1577485.8 | M6: =L6/I6 -> 15.915528
A7: 10 | B7: 5 | C7: 30038.633 | D7: 10 | E7: 0.0003329046 | F7: =B7/2 -> 2.5 | G7: =(B7*E7)/(1+(B7-F7)*E7) -> 0.0016631388 | H7: =1-G7 -> 0.99833686 | I7: =I6*H6 -> 98947.879 | J7: =I7-I8 -> 164.56406 | K7: =(B7+I8)+(F7*J7) -> 99199.725 | L7: =L8+K7 -> 1478112.2 | M7: =L7/I7 -> 14.938291
A8: 15 | B8: 5 | C8: 29934.746 | D8: 18 | E8: 0.0006013079 | F8: =B8/2 -> 2.5 | G8: =(B8*E8)/(1+(B8-F8)*E8) -> 0.0030020266 | H8: =1-G8 -> 0.99699797 | I8: =I7*H7 -> 98783.315 | J8: =I8-I9 -> 296.55014 | K8: =(B8+I9)+(F8*J8) -> 99233.14 | L8: =L9+K8 -> 1378912.5 | M8: =L8/I8 -> 13.958962
A9: 20 | B9: 5 | C9: 29632.306 | D9: 20 | E9: 0.000674939 | F9: =B9/2 -> 2.5 | G9: =(B9*E9)/(1+(B9-F9)*E9) -> 0.0033690103 | H9: =1-G9 -> 0.99663099 | I9: =I8*H8 -> 98486.764 | J9: =I9-I10 -> 331.80292 | K9: =(B9+I10)+(F9*J9) -> 98989.469 | L9: =L10+K9 -> 1279679.4 | M9: =L9/I9 -> 12.993415
A10: 25 | B10: 5 | C10: 29815.427 | D10: 35 | E10: 0.0011738889 | F10: =B10/2 -> 2.5 | G10: =(B10*E10)/(1+(B10-F10)*E10) -> 0.0058522697 | H10: =1-G10 -> 0.99414773 | I10: =I9*H9 -> 98154.962 | J10: =I10-I11 -> 574.42931 | K10: =(B10+I11)+(F10*J10) -> 99021.606 | L10: =L11+K10 -> 1180689.9 | M10: =L10/I10 -> 12.028836
A11: 30 | B11: 5 | C11: 30340.757 | D11: 47 | E11: 0.0015490714 | F11: =B11/2 -> 2.5 | G11: =(B11*E11)/(1+(B11-F11)*E11) -> 0.0077154774 | H11: =1-G11 -> 0.99228452 | I11: =I10*H10 -> 97580.532 | J11: =I11-I12 -> 752.88039 | K11: =(B11+I12)+(F11*J11) -> 98714.853 | L11: =L12+K11 -> 1081668.3 | M11: =L11/I11 -> 11.084878
A12: 35 | B12: 5 | C12: 28389.017 | D12: 59 | E12: 0.0020782685 | F12: =B12/2 -> 2.5 | G12: =(B12*E12)/(1+(B12-F12)*E12) -> 0.010337632 | H12: =1-G12 -> 0.98966237 | I12: =I11*H11 -> 96827.652 | J12: =I12-I13 -> 1000.9686 | K12: =(B12+I13)+(F12*J12) -> 98334.105 | L12: =L13+K12 -> 982953.44 | M12: =L12/I12 -> 10.151578
A13: 40 | B13: 5 | C13: 27191.98 | D13: 65 | E13: 0.0023904107 | F13: =B13/2 -> 2.5 | G13: =(B13*E13)/(1+(B13-F13)*E13) -> 0.011881052 | H13: =1-G13 -> 0.98811895 | I13: =I12*H12 -> 95826.683 | J13: =I13-I14 -> 1138.5218 | K13: =(B13+I14)+(F13*J13) -> 97539.466 | L13: =L14+K13 -> 884619.34 | M13: =L13/I13 -> 9.2314511
A14: 45 | B14: 5 | C14: 24901.682 | D14: 114 | E14: 0.0045780039 | F14: =B14/2 -> 2.5 | G14: =(B14*E14)/(1+(B14-F14)*E14) -> 0.022631007 | H14: =1-G14 -> 0.97736899 | I14: =I13*H13 -> 94688.161 | J14: =I14-I15 -> 2142.8885 | K14: =(B14+I15)+(F14*J14) -> 97907.494 | L14: =L15+K14 -> 787079.87 | M14: =L14/I14 -> 8.3123366
A15: 50 | B15: 5 | C15: 22463.343 | D15: 149 | E15: 0.0066330287 | F15: =B15/2 -> 2.5 | G15: =(B15*E15)/(1+(B15-F15)*E15) -> 0.032624151 | H15: =1-G15 -> 0.96737585 | I15: =I14*H14 -> 92545.273 | J15: =I15-I16 -> 3019.211 | K15: =(B15+I16)+(F15*J15) -> 97079.089 | L15: =L16+K15 -> 689172.38 | M15: =L15/I15 -> 7.4468674
A16: 55 | B16: 5 | C16: 19058.882 | D16: 199 | E16: 0.010441326 | F16: =B16/2 -> 2.5 | G16: =(B16*E16)/(1+(B16-F16)*E16) -> 0.050878531 | H16: =1-G16 -> 0.94912147 | I16: =I15*H15 -> 89526.062 | J16: =I16-I17 -> 4554.9545 | K16: =(B16+I17)+(F16*J16) -> 96363.494 | L16: =L17+K16 -> 592093.29 | M16: =L16/I16 -> 6.6136416
A17: 60 | B17: 5 | C17: 16373.749 | D17: 231 | E17: 0.014107948 | F17: =B17/2 -> 2.5 | G17: =(B17*E17)/(1+(B17-F17)*E17) -> 0.068136572 | H17: =1-G17 -> 0.93186343 | I17: =I16*H16 -> 84971.108 | J17: =I17-I18 -> 5789.64 | K17: =(B17+I18)+(F17*J17) -> 93660.567 | L17: =L18+K17 -> 495729.8 | M17: =L17/I17 -> 5.8340983
... A21: 80 | B21: 5 | C21: 3968.117 | D21: 312 | E21: 0.078626706 | F21: =B21/2 -> 2.5 | G21: =(B21*E21)/(1+(B21-F21)*E21) -> 0.32855127 | H21: =1-G21 -> 0.67144873 | I21: =I20*H20 -> 44992.11 | J21: =I21-I22 -> 14782.215 | K21: =(B21+I22)+(F21*J21) -> 67170.432 | L21: =L22+K21 -> 142700.17 | M21: =L21/I21 -> 3.171671
A22: 85+ | B22: 5 | C22: 3571.617 | D22: 603 | E22: 0.16883111 | F22: =B22/2 -> 2.5 | G22: =(B22*E22)/(1+(B22-F22)*E22) -> 0.59360716 | H22: =1-G22 -> 0.40639284 | I22: =I21*H21 -> 30209.895 | J22: =I22-I23 -> 30209.895 | K22: =(B22+I23)+(F22*J22) -> 75529.738 | L22: =L23+K22 -> 75529.738 | M22: =L22/I22 -> 2.5001655

Sheet GrafH10-19
B2: x(edad) | C2: nmx 2010 | D2: nmx2019 | F2: x(edad) | G2: nqx 2010 | H2: nqx 2019 | J2: x(edad) | K2: lx 2010 | L2: lx 2019 | N2: x(edad) | O2: ndx 2010 | P2: ndx 2019 | R2: x(edad) | S2: ex 2010 | T2: ex 2019
B3: 0 | C3: 0.013635 | D3: 0.0096054723 | F3: 0 | G3: ='2010H'!G4 -> 0.013468106 | H3: ='2019H'!G4 -> 0.0095213225 | J3: 0 | K3: ='2010H'!I4 -> 100000 | L3: ='2019H'!I4 -> 100000 | N3: 0 | O3: ='2010H'!J4 -> 1346.8106 | P3: ='2019H'!J4 -> 952.13225 | R3: 0 | S3: ='2010H'!M4 -> 17.349294 | T3: ='2019H'!M4 -> 16.942234
B4: 1 | C4: 0.0005455632 | D4: 0.0005000097 | F4: 1 | G4: ='2010H'!G5 -> 0.002179282 | H4: ='2019H'!G5 -> 0.0019975492 | J4: 1 | K4: ='2010H'!I5 -> 98653.189 | L4: ='2019H'!I5 -> 99047.868 | N4: 1 | O4: ='2010H'!J5 -> 214.99312 | P4: ='2019H'!J5 -> 197.85299 | R4: 1 | S4: ='2010H'!M5 -> 16.584891 | T4: ='2019H'!M5 -> 16.104319
B5: 5 | C5: 0.0002537501 | D5: 0.0001956181 | F5: 5 | G5: ='2010H'!G6 -> 0.0012679461 | H5: ='2019H'!G6 -> 0.0009776124 | J5: 5 | K5: ='2010H'!I6 -> 98438.196 | L5: ='2019H'!I6 -> 98850.015 | N5: 5 | O5: ='2010H'!J6 -> 124.81433 | P5: ='2019H'!J6 -> 96.637 | R5: 5 | S5: ='2010H'!M6 -> 15.617794 | T5: ='2019H'!M6 -> 15.133495
B6: 10 | C6: 0.0001853201 | D6: 0.0002259275 | F6: 10 | G6: ='2010H'!G7 -> 0.0009261714 | H6: ='2019H'!G7 -> 0.0011289998 | J6: 10 | K6: ='2010H'!I7 -> 98313.382 | L6: ='2019H'!I7 -> 98753.378 | N6: 10 | O6: ='2010H'!J7 -> 91.055043 | P6: ='2019H'!J7 -> 111.49255 | R6: 10 | S6: ='2010H'!M7 -> 14.634397 | T6: ='2019H'!M7 -> 14.145807
B7: 15 | C7: 0.0010190929 | D7: 0.0018194659 | F7: 15 | G7: ='2010H'!G8 -> 0.0050825156 | H7: ='2019H'!G8 -> 0.0090561362 | J7: 15 | K7: ='2010H'!I8 -> 98222.327 | L7: ='2019H'!I8 -> 98641.885 | N7: 15 | O7: ='2010H'!J8 -> 499.21651 | P7: ='2019H'!J8 -> 893.31434 | R7: 15 | S7: ='2010H'!M8 -> 13.645595 | T7: ='2019H'!M8 -> 13.15892
B8: 20 | C8: 0.0015214147 | D8: 0.0041788538 | F8: 20 | G8: ='2010H'!G9 -> 0.0075782494 | H8: ='2019H'!G9 -> 0.020678241 | J8: 20 | K8: ='2010H'!I9 -> 97723.11 | L8: ='2019H'!I9 -> 97748.571 | N8: 20 | O8: ='2010H'!J9 -> 740.5701 | P8: ='2019H'!J9 -> 2021.2685 | R8: 20 | S8: ='2010H'!M9 -> 12.702481 | T8: ='2019H'!M9 -> 12.256279
B9: 25 | C9: 0.0020734015 | D9: 0.0051347528 | F9: 25 | G9: ='2010H'!G10 -> 0.010313547 | H9: ='2019H'!G10 -> 0.02534837 | J9: 25 | K9: ='2010H'!I10 -> 96982.54 | L9: ='2019H'!I10 -> 95727.302 | N9: 25 | O9: ='2010H'!J10 -> 1000.234 | P9: ='2019H'!J10 -> 2426.5311 | R9: 25 | S9: ='2010H'!M10 -> 11.780337 | T9: ='2019H'!M10 -> 11.462229
B10: 30 | C10: 0.0025591994 | D10: 0.0050554005 | F10: 30 | G10: ='2010H'!G11 -> 0.012714649 | H10: ='2019H'!G11 -> 0.024961526 | J10: 30 | K10: ='2010H'!I11 -> 95982.306 | L10: ='2019H'!I11 -> 93300.771 | N10: 30 | O10: ='2010H'!J11 -> 1220.3813 | P10: ='2019H'!J11 -> 2328.9296 | R10: 30 | S10: ='2010H'!M11 -> 10.876995 | T10: ='2019H'!M11 -> 10.695262
B11: 35 | C11: 0.0034778306 | D11: 0.0047608437 | F11: 35 | G11: ='2010H'!G12 -> 0.017239265 | H11: ='2019H'!G12 -> 0.023524231 | J11: 35 | K11: ='2010H'!I12 -> 94761.925 | L11: ='2019H'!I12 -> 90971.842 | N11: 35 | O11: ='2010H'!J12 -> 1633.6259 | P11: ='2019H'!J12 -> 2140.0426 | R11: 35 | S11: ='2010H'!M12 -> 9.9848247 | T11: ='2019H'!M12 -> 9.9050104
B12: 40 | C12: 0.0042950211 | D12: 0.0062979058 | F12: 40 | G12: ='2010H'!G13 -> 0.021246965 | H12: ='2019H'!G13 -> 0.031001419 | J12: 40 | K12: ='2010H'!I13 -> 93128.299 | L12: ='2019H'!I13 -> 88831.799 | N12: 40 | O12: ='2010H'!J13 -> 1978.6937 | P12: ='2019H'!J13 -> 2753.9118 | R12: 40 | S12: ='2010H'!M13 -> 9.1160673 | T12: ='2019H'!M13 -> 9.0833479
B13: 45 | C13: 0.0053717898 | D13: 0.00668994 | F13: 45 | G13: ='2010H'!G14 -> 0.026503027 | H13: ='2019H'!G14 -> 0.032899461 | J13: 45 | K13: ='2010H'!I14 -> 91149.605 | L13: ='2019H'!I14 -> 86077.887 | N13: 45 | O13: ='2010H'!J14 -> 2415.7405 | P13: ='2019H'!J14 -> 2831.9161 | R13: 45 | S13: ='2010H'!M14 -> 8.2596354 | T13: ='2019H'!M14 -> 8.2939125
B14: 50 | C14: 0.0071097828 | D14: 0.0082330699 | F14: 50 | G14: ='2010H'!G15 -> 0.034928086 | H14: ='2019H'!G15 -> 0.040335144 | J14: 50 | K14: ='2010H'!I15 -> 88733.865 | L14: ='2019H'!I15 -> 83245.971 | N14: 50 | O14: ='2010H'!J15 -> 3099.3041 | P14: ='2019H'!J15 -> 3357.7383 | R14: 50 | S14: ='2010H'!M15 -> 7.4163826 | T14: ='2019H'!M15 -> 7.4909536
... B20: 80 | C20: 0.076526111 | D20: 0.061665684 | F20: 80 | G20: ='2010H'!G21 -> 0.32118328 | H20: ='2019H'!G21 -> 0.26714432 | J20: 80 | K20: ='2010H'!I21 -> 43031.953 | L20: ='2019H'!I21 -> 42742.465 | N20: 80 | O20: ='2010H'!J21 -> 13821.144 | P20: ='2019H'!J21 -> 11418.407 | R20: 80 | S20: ='2010H'!M21 -> 3.1790491 | T20: ='2019H'!M21 -> 3.2330896
B21: 85+ | C21: 0.13412595 | D21: 0.14535377 | F21: 85+ | G21: ='2010H'!G22 -> 0.50222594 | H21: ='2019H'!G22 -> 0.5330623 | J21: 85+ | K21: ='2010H'!I22 -> 29210.809 | L21: ='2019H'!I22 -> 31324.058 | N21: 85+ | O21: ='2010H'!J22 -> 29210.809 | P21: ='2019H'!J22 -> 31324.058 | R21: 85+ | S21: ='2010H'!M22 -> 2.5001712 | T21: ='2019H'!M22 -> 2.5001596

Sheet GrafH19-21
B2: x(edad) | C2: nmx 2019 | D2: nmx2021 | F2: x(edad) | G2: nqx 2019 | H2: nqx 2021 | J2: x(edad) | K2: lx 2019 | L2: lx 2021 | N2: x(edad) | O2: ndx 2019 | P2: ndx 2021 | R2: x(edad) | S2: ex 2019 | T2: ex 2021
B3: 0 | C3: ='2019H'!E4 -> 0.0096054723 | D3: ='2021H'!E4 -> 0.010805039 | F3: 0 | G3: ='2019H'!G4 -> 0.0095213225 | H3: ='2021H'!G4 -> 0.01069906 | J3: 0 | K3: ='2019H'!I4 -> 100000 | L3: ='2021H'!I4 -> 100000 | N3: 0 | O3: ='2019H'!J4 -> 952.13225 | P3: ='2021H'!J4 -> 1069.906 | R3: 0 | S3: ='2019H'!M4 -> 16.942234 | T3: ='2021H'!M4 -> 16.069741
B4: 1 | C4: ='2019H'!E5 -> 0.0005000097 | D4: ='2021H'!E5 -> 0.0005107998 | F4: 1 | G4: ='2019H'!G5 -> 0.0019975492 | H4: ='2021H'!G5 -> 0.0020405992 | J4: 1 | K4: ='2019H'!I5 -> 99047.868 | L4: ='2021H'!I5 -> 98930.094 | N4: 1 | O4: ='2019H'!J5 -> 197.85299 | P4: ='2021H'!J5 -> 201.87667 | R4: 1 | S4: ='2019H'!M5 -> 16.104319 | T4: ='2021H'!M5 -> 15.242621
B5: 5 | C5: ='2019H'!E6 -> 0.0001956181 | D5: ='2021H'!E6 -> 0.0002934744 | F5: 5 | G5: ='2019H'!G6 -> 0.0009776124 | H5: ='2021H'!G6 -> 0.0014662962 | J5: 5 | K5: ='2019H'!I6 -> 98850.015 | L5: ='2021H'!I6 -> 98728.217 | N5: 5 | O5: ='2019H'!J6 -> 96.637 | P5: ='2021H'!J6 -> 144.76481 | R5: 5 | S5: ='2019H'!M6 -> 15.133495 | T5: ='2021H'!M6 -> 14.27067
B6: 10 | C6: ='2019H'!E7 -> 0.0002259275 | D6: ='2021H'!E7 -> 0.000258366 | F6: 10 | G6: ='2019H'!G7 -> 0.0011289998 | H6: ='2021H'!G7 -> 0.0012909961 | J6: 10 | K6: ='2019H'!I7 -> 98753.378 | L6: ='2021H'!I7 -> 98583.453 | N6: 10 | O6: ='2019H'!J7 -> 111.49255 | P6: ='2021H'!J7 -> 127.27086 | R6: 10 | S6: ='2019H'!M7 -> 14.145807 | T6: ='2021H'!M7 -> 13.287904
B7: 15 | C7: ='2019H'!E8 -> 0.0018194659 | D7: ='2021H'!E8 -> 0.0016376693 | F7: 15 | G7: ='2019H'!G8 -> 0.0090561362 | H7: ='2021H'!G8 -> 0.0081549587 | J7: 15 | K7: ='2019H'!I8 -> 98641.885 | L7: ='2021H'!I8 -> 98456.182 | N7: 15 | O7: ='2019H'!J8 -> 893.31434 | P7: ='2021H'!J8 -> 802.90609 | R7: 15 | S7: ='2019H'!M8 -> 13.15892 | T7: ='2021H'!M8 -> 12.301798
B8: 20 | C8: ='2019H'!E9 -> 0.0041788538 | D8: ='2021H'!E9 -> 0.0041502237 | F8: 20 | G8: ='2019H'!G9 -> 0.020678241 | H8: ='2021H'!G9 -> 0.020538025 | J8: 20 | K8: ='2019H'!I9 -> 97748.571 | L8: ='2021H'!I9 -> 97653.276 | N8: 20 | O8: ='2019H'!J9 -> 2021.2685 | P8: ='2021H'!J9 -> 2005.6054 | R8: 20 | S8: ='2019H'!M9 -> 12.256279 | T8: ='2021H'!M9 -> 11.382337
B9: 25 | C9: ='2019H'!E10 -> 0.0051347528 | D9: ='2021H'!E10 -> 0.0054616357 | F9: 25 | G9: ='2019H'!G10 -> 0.02534837 | H9: ='2021H'!G10 -> 0.026940333 | J9: 25 | K9: ='2019H'!I10 -> 95727.302 | L9: ='2021H'!I10 -> 95647.67 | N9: 25 | O9: ='2019H'!J10 -> 2426.5311 | P9: ='2021H'!J10 -> 2576.7801 | R9: 25 | S9: ='2019H'!M10 -> 11.462229 | T9: ='2021H'!M10 -> 10.568536
B10: 30 | C10: ='2019H'!E11 -> 0.0050554005 | D10: ='2021H'!E11 -> 0.0055138651 | F10: 30 | G10: ='2019H'!G11 -> 0.024961526 | H10: ='2021H'!G11 -> 0.027194459 | J10: 30 | K10: ='2019H'!I11 -> 93300.771 | L10: ='2021H'!I11 -> 93070.89 | N10: 30 | O10: ='2019H'!J11 -> 2328.9296 | P10: ='2021H'!J11 -> 2531.0125 | R10: 30 | S10: ='2019H'!M11 -> 10.695262 | T10: ='2021H'!M11 -> 9.7918693
B11: 35 | C11: ='2019H'!E12 -> 0.0047608437 | D11: ='2021H'!E12 -> 0.006923784 | F11: 35 | G11: ='2019H'!G12 -> 0.023524231 | H11: ='2021H'!G12 -> 0.034029881 | J11: 35 | K11: ='2019H'!I12 -> 90971.842 | L11: ='2021H'!I12 -> 90539.878 | N11: 35 | O11: ='2019H'!J12 -> 2140.0426 | P11: ='2021H'!J12 -> 3081.0613 | R11: 35 | S11: ='2019H'!M12 -> 9.9050104 | T11: ='2021H'!M12 -> 8.9956559
B12: 40 | C12: ='2019H'!E13 -> 0.0062979058 | D12: ='2021H'!E13 -> 0.0078518669 | F12: 40 | G12: ='2019H'!G13 -> 0.031001419 | H12: ='2021H'!G13 -> 0.038503523 | J12: 40 | K12: ='2019H'!I13 -> 88831.799 | L12: ='2021H'!I13 -> 87458.816 | N12: 40 | O12: ='2019H'!J13 -> 2753.9118 | P12: ='2021H'!J13 -> 3367.4726 | R12: 40 | S12: ='2019H'!M13 -> 9.0833479 | T12: ='2021H'!M13 -> 8.2244323
B13: 45 | C13: ='2019H'!E14 -> 0.00668994 | D13: ='2021H'!E14 -> 0.0085380395 | F13: 45 | G13: ='2019H'!G14 -> 0.032899461 | H13: ='2021H'!G14 -> 0.041798015 | J13: 45 | K13: ='2019H'!I14 -> 86077.887 | L13: ='2021H'!I14 -> 84091.344 | N13: 45 | O13: ='2019H'!J14 -> 2831.9161 | P13: ='2021H'!J14 -> 3514.8512 | R13: 45 | S13: ='2019H'!M14 -> 8.2939125 | T13: ='2021H'!M14 -> 7.4536101
B14: 50 | C14: ='2019H'!E15 -> 0.0082330699 | D14: ='2021H'!E15 -> 0.01333842 | F14: 50 | G14: ='2019H'!G15 -> 0.040335144 | H14: ='2021H'!G15 -> 0.064539948 | J14: 50 | K14: ='2019H'!I15 -> 83245.971 | L14: ='2021H'!I15 -> 80576.493 | N14: 50 | O14: ='2019H'!J15 -> 3357.7383 | P14: ='2021H'!J15 -> 5200.4026 | R14: 50 | S14: ='2019H'!M15 -> 7.4909536 | T14: ='2021H'!M15 -> 6.6696309
... B20: 80 | C20: ='2019H'!E21 -> 0.061665684 | D20: ='2021H'!E21 -> 0.10923592 | F20: 80 | G20: ='2019H'!G21 -> 0.26714432 | H20: ='2021H'!G21 -> 0.42901891 | J20: 80 | K20: ='2019H'!I21 -> 42742.465 | L20: ='2021H'!I21 -> 26840.139 | N20: 80 | O20: ='2019H'!J21 -> 11418.407 | P20: ='2021H'!J21 -> 11514.927 | R20: 80 | S20: ='2019H'!M21 -> 3.2330896 | T20: ='2021H'!M21 -> 3.0713537
B21: 85+ | C21: ='2019H'!E22 -> 0.14535377 | D21: ='2021H'!E22 -> 0.20385816 | F21: 85+ | G21: ='2019H'!G22 -> 0.5330623 | H21: ='2021H'!G22 -> 0.67518558 | J21: 85+ | K21: ='2019H'!I22 -> 31324.058 | L21: ='2021H'!I22 -> 15325.212 | N21: 85+ | O21: ='2019H'!J22 -> 31324.058 | P21: ='2021H'!J22 -> 15325.212 | R21: 85+ | S21: ='2019H'!M22 -> 2.5001596 | T21: ='2021H'!M22 -> 2.5003263

Sheet GrafF10-19
B2: x(edad) | C2: nmx 2010 | D2: nmx2019 | F2: x(edad) | G2: nqx 2010 | H2: nqx 2019 | J2: x(edad) | K2: lx 2010 | L2: lx 2019 | N2: x(edad) | O2: ndx 2010 | P2: ndx 2019 | R2: x(edad) | S2: ex 2010 | T2: ex 2019
B3: 0 | C3: ='2010F'!E4 -> 0.011874603 | D3: ='2019F'!E4 -> 0.0073501791 | F3: 0 | G3: ='2010F'!G4 -> 0.011747142 | H3: ='2019F'!G4 -> 0.0073004677 | J3: 0 | K3: ='2010F'!I4 -> 100000 | L3: ='2019F'!I4 -> 100000 | N3: 0 | O3: ='2010F'!J4 -> 1174.7142 | P3: ='2019F'!J4 -> 730.04677 | R3: 0 | S3: ='2010F'!M4 -> 18.415686 | T3: ='2019F'!M4 -> 18.478635
B4: 1 | C4: ='2010F'!E5 -> 0.0005719192 | D4: ='2019F'!E5 -> 0.0007953133 | F4: 1 | G4: ='2010F'!G5 -> 0.0022844157 | H4: ='2019F'!G5 -> 0.0031749678 | J4: 1 | K4: ='2010F'!I5 -> 98825.286 | L4: ='2019F'!I5 -> 99269.953 | N4: 1 | O4: ='2010F'!J5 -> 225.75804 | P4: ='2019F'!J5 -> 315.17891 | R4: 1 | S4: ='2010F'!M5 -> 17.633554 | T4: ='2019F'!M5 -> 17.613979
B5: 5 | C5: ='2010F'!E6 -> 0.0002123948 | D5: ='2019F'!E6 -> 0.0002716979 | F5: 5 | G5: ='2010F'!G6 -> 0.0010614104 | H5: ='2019F'!G6 -> 0.0013575674 | J5: 5 | K5: ='2010F'!I6 -> 98599.528 | L5: ='2019F'!I6 -> 98954.774 | N5: 5 | O5: ='2010F'!J6 -> 104.65456 | P5: ='2019F'!J6 -> 134.33777 | R5: 5 | S5: ='2010F'!M6 -> 16.670445 | T5: ='2019F'!M6 -> 16.665228
B6: 10 | C6: ='2010F'!E7 -> 0.0002064693 | D6: ='2019F'!E7 -> 0.0001677752 | F6: 10 | G6: ='2010F'!G7 -> 0.0010318139 | H6: ='2019F'!G7 -> 0.00083852429 | J6: 10 | K6: ='2010F'!I7 -> 98494.873 | L6: ='2019F'!I7 -> 98820.437 | N6: 10 | O6: ='2010F'!J7 -> 101.62838 | P6: ='2019F'!J7 -> 82.863336 | R6: 10 | S6: ='2010F'!M7 -> 15.685451 | T6: ='2019F'!M7 -> 15.684434
B7: 15 | C7: ='2010F'!E8 -> 0.0003539985 | D7: ='2019F'!E8 -> 0.0004653545 | F7: 15 | G7: ='2010F'!G8 -> 0.0017684274 | H7: ='2019F'!G8 -> 0.0023240687 | J7: 15 | K7: ='2010F'!I8 -> 98393.245 | L7: ='2019F'!I8 -> 98737.573 | N7: 15 | O7: ='2010F'!J8 -> 174.00131 | P7: ='2019F'!J8 -> 229.4729 | R7: 15 | S7: ='2010F'!M8 -> 14.699019 | T7: ='2019F'!M8 -> 14.695448
B8: 20 | C8: ='2010F'!E9 -> 0.0004426227 | D8: ='2019F'!E9 -> 0.0011073519 | F8: 20 | G8: ='2010F'!G9 -> 0.0022106673 | H8: ='2019F'!G9 -> 0.005521474 | J8: 20 | K8: ='2010F'!I9 -> 98219.244 | L8: ='2019F'!I9 -> 98508.1 | N8: 20 | O8: ='2010F'!J9 -> 217.13007 | P8: ='2019F'!J9 -> 543.90991 | R8: 20 | S8: ='2010F'!M9 -> 13.720579 | T8: ='2019F'!M9 -> 13.723806
B9: 25 | C9: ='2010F'!E10 -> 0.0007174503 | D9: ='2019F'!E10 -> 0.001228264 | F9: 25 | G9: ='2010F'!G10 -> 0.0035808288 | H9: ='2019F'!G10 -> 0.0061225198 | J9: 25 | K9: ='2010F'!I10 -> 98002.113 | L9: ='2019F'!I10 -> 97964.19 | N9: 25 | O9: ='2010F'!J10 -> 350.92879 | P9: ='2019F'!J10 -> 599.7877 | R9: 25 | S9: ='2010F'!M10 -> 12.745388 | T9: ='2019F'!M10 -> 12.786071
B10: 30 | C10: ='2010F'!E11 -> 0.0009925144 | D10: ='2019F'!E11 -> 0.0010174172 | F10: 30 | G10: ='2010F'!G11 -> 0.0049502889 | H10: ='2019F'!G11 -> 0.0050741796 | J10: 30 | K10: ='2010F'!I11 -> 97651.185 | L10: ='2019F'!I11 -> 97364.403 | N10: 30 | O10: ='2010F'!J11 -> 483.40158 | P10: ='2019F'!J11 -> 494.04447 | R10: 30 | S10: ='2010F'!M11 -> 11.782156 | T10: ='2019F'!M11 -> 11.849385
B11: 35 | C11: ='2010F'!E12 -> 0.0008317532 | D11: ='2019F'!E12 -> 0.0011175648 | F11: 35 | G11: ='2010F'!G12 -> 0.0041501363 | H11: ='2019F'!G12 -> 0.0055722556 | J11: 35 | K11: ='2010F'!I12 -> 97167.783 | L11: ='2019F'!I12 -> 96870.358 | N11: 35 | O11: ='2010F'!J12 -> 403.25954 | P11: ='2019F'!J12 -> 539.7864 | R11: 35 | S11: ='2010F'!M12 -> 10.828282 | T11: ='2019F'!M12 -> 10.897015
B12: 40 | C12: ='2010F'!E13 -> 0.0014231538 | D12: ='2019F'!E13 -> 0.0016911074 | F12: 40 | G12: ='2010F'!G13 -> 0.0070905417 | H12: ='2019F'!G13 -> 0.0084199394 | J12: 40 | K12: ='2010F'!I13 -> 96764.524 | L12: ='2019F'!I13 -> 96330.572 | N12: 40 | O12: ='2010F'!J13 -> 686.11289 | P12: ='2019F'!J13 -> 811.09758 | R12: 40 | S12: ='2010F'!M13 -> 9.8629381 | T12: ='2019F'!M13 -> 9.944016
B13: 45 | C13: ='2010F'!E14 -> 0.0023246449 | D13: ='2019F'!E14 -> 0.003142511 | F13: 45 | G13: ='2010F'!G14 -> 0.011556065 | H13: ='2019F'!G14 -> 0.015590075 | J13: 45 | K13: ='2010F'!I14 -> 96078.411 | L13: ='2019F'!I14 -> 95519.474 | N13: 45 | O13: ='2010F'!J14 -> 1110.2884 | P13: ='2019F'!J14 -> 1489.1558 | R13: 45 | S13: ='2010F'!M14 -> 8.9154661 | T13: ='2019F'!M14 -> 9.007174
B14: 50 | C14: ='2010F'!E15 -> 0.0031791096 | D14: ='2019F'!E15 -> 0.0038021215 | F14: 50 | G14: ='2010F'!G15 -> 0.01577021 | H14: ='2019F'!G15 -> 0.018831607 | J14: 50 | K14: ='2010F'!I15 -> 94968.122 | L14: ='2019F'!I15 -> 94030.318 | N14: 50 | O14: ='2010F'!J15 -> 1497.6672 | P14: ='2019F'!J15 -> 1770.742 | R14: 50 | S14: ='2010F'!M15 -> 7.9904177 | T14: ='2019F'!M15 -> 8.1101748
... B20: 80 | C20: ='2010F'!E21 -> 0.058357772 | D20: ='2019F'!E21 -> 0.056122465 | F20: 80 | G20: ='2010F'!G21 -> 0.25463852 | H20: ='2019F'!G21 -> 0.24608507 | J20: 80 | K20: ='2010F'!I21 -> 57243.623 | L20: ='2019F'!I21 -> 60837.395 | N20: 80 | O20: ='2010F'!J21 -> 14576.431 | P20: ='2019F'!J21 -> 14971.175 | R20: 80 | S20: ='2010F'!M21 -> 3.2455362 | T20: ='2019F'!M21 -> 3.2540793
B21: 85+ | C21: ='2010F'!E22 -> 0.13140791 | D21: ='2019F'!E22 -> 0.13011203 | F21: 85+ | G21: ='2010F'!G22 -> 0.49456513 | H21: ='2019F'!G22 -> 0.49088502 | J21: 85+ | K21: ='2010F'!I22 -> 42667.192 | L21: ='2019F'!I22 -> 45866.22 | N21: 85+ | O21: ='2010F'!J22 -> 42667.192 | P21: ='2019F'!J22 -> 45866.22 | R21: 85+ | S21: ='2010F'!M22 -> 2.5001172 | T21: ='2019F'!M22 -> 2.500109

Sheet GrafF19-21
B2: x(edad) | C2: nmx 2019 | D2: nmx2021 | F2: x(edad) | G2: nqx 2019 | H2: nqx 2021 | J2: x(edad) | K2: lx 2019 | L2: lx 2021 | N2: x(edad) | O2: ndx 2019 | P2: ndx 2021 | R2: x(edad) | S2: ex 2019 | T2: ex 2021
B3: 0 | C3: ='2019F'!E4 -> 0.0073501791 | D3: ='2021F'!E4 -> 0.007952866 | F3: 0 | G3: ='2019F'!G4 -> 0.0073004677 | H3: ='2021F'!G4 -> 0.0078948055 | J3: 0 | K3: ='2019F'!I4 -> 100000 | L3: ='2021F'!I4 -> 100000 | N3: 0 | O3: ='2019F'!J4 -> 730.04677 | P3: ='2021F'!J4 -> 789.48055 | R3: 0 | S3: ='2019F'!M4 -> 18.478635 | T3: ='2021F'!M4 -> 17.760194
B4: 1 | C4: ='2019F'!E5 -> 0.0007953133 | D4: ='2021F'!E5 -> 0.0002379462 | F4: 1 | G4: ='2019F'!G5 -> 0.0031749678 | H4: ='2021F'!G5 -> 0.0009512212 | J4: 1 | K4: ='2019F'!I5 -> 99269.953 | L4: ='2021F'!I5 -> 99210.519 | N4: 1 | O4: ='2019F'!J5 -> 315.17891 | P4: ='2021F'!J5 -> 94.371149 | R4: 1 | S4: ='2019F'!M5 -> 17.613979 | T4: ='2021F'!M5 -> 16.900914
B5: 5 | C5: ='2019F'!E6 -> 0.0002716979 | D5: ='2021F'!E6 -> 0.0003398287 | F5: 5 | G5: ='2019F'!G6 -> 0.0013575674 | H5: ='2021F'!G6 -> 0.0016977012 | J5: 5 | K5: ='2019F'!I6 -> 98954.774 | L5: ='2021F'!I6 -> 99116.148 | N5: 5 | O5: ='2019F'!J6 -> 134.33777 | P5: ='2021F'!J6 -> 168.2696 | R5: 5 | S5: ='2019F'!M6 -> 16.665228 | T5: ='2021F'!M6 -> 15.915528
B6: 10 | C6: ='2019F'!E7 -> 0.0001677752 | D6: ='2021F'!E7 -> 0.0003329046 | F6: 10 | G6: ='2019F'!G7 -> 0.00083852429 | H6: ='2021F'!G7 -> 0.0016631388 | J6: 10 | K6: ='2019F'!I7 -> 98820.437 | L6: ='2021F'!I7 -> 98947.879 | N6: 10 | O6: ='2019F'!J7 -> 82.863336 | P6: ='2021F'!J7 -> 164.56406 | R6: 10 | S6: ='2019F'!M7 -> 15.684434 | T6: ='2021F'!M7 -> 14.938291
B7: 15 | C7: ='2019F'!E8 -> 0.0004653545 | D7: ='2021F'!E8 -> 0.0006013079 | F7: 15 | G7: ='2019F'!G8 -> 0.0023240687 | H7: ='2021F'!G8 -> 0.0030020266 | J7: 15 | K7: ='2019F'!I8 -> 98737.573 | L7: ='2021F'!I8 -> 98783.315 | N7: 15 | O7: ='2019F'!J8 -> 229.4729 | P7: ='2021F'!J8 -> 296.55014 | R7: 15 | S7: ='2019F'!M8 -> 14.695448 | T7: ='2021F'!M8 -> 13.958962
B8: 20 | C8: ='2019F'!E9 -> 0.0011073519 | D8: ='2021F'!E9 -> 0.000674939 | F8: 20 | G8: ='2019F'!G9 -> 0.005521474 | H8: ='2021F'!G9 -> 0.0033690103 | J8: 20 | K8: ='2019F'!I9 -> 98508.1 | L8: ='2021F'!I9 -> 98486.764 | N8: 20 | O8: ='2019F'!J9 -> 543.90991 | P8: ='2021F'!J9 -> 331.80292 | R8: 20 | S8: ='2019F'!M9 -> 13.723806 | T8: ='2021F'!M9 -> 12.993415
B9: 25 | C9: ='2019F'!E10 -> 0.001228264 | D9: ='2021F'!E10 -> 0.0011738889 | F9: 25 | G9: ='2019F'!G10 -> 0.0061225198 | H9: ='2021F'!G10 -> 0.0058522697 | J9: 25 | K9: ='2019F'!I10 -> 97964.19 | L9: ='2021F'!I10 -> 98154.962 | N9: 25 | O9: ='2019F'!J10 -> 599.7877 | P9: ='2021F'!J10 -> 574.42931 | R9: 25 | S9: ='2019F'!M10 -> 12.786071 | T9: ='2021F'!M10 -> 12.028836
B10: 30 | C10: ='2019F'!E11 -> 0.0010174172 | D10: ='2021F'!E11 -> 0.0015490714 | F10: 30 | G10: ='2019F'!G11 -> 0.0050741796 | H10: ='2021F'!G11 -> 0.0077154774 | J10: 30 | K10: ='2019F'!I11 -> 97364.403 | L10: ='2021F'!I11 -> 97580.532 | N10: 30 | O10: ='2019F'!J11 -> 494.04447 | P10: ='2021F'!J11 -> 752.88039 | R10: 30 | S10: ='2019F'!M11 -> 11.849385 | T10: ='2021F'!M11 -> 11.084878
B11: 35 | C11: ='2019F'!E12 -> 0.0011175648 | D11: ='2021F'!E12 -> 0.0020782685 | F11: 35 | G11: ='2019F'!G12 -> 0.0055722556 | H11: ='2021F'!G12 -> 0.010337632 | J11: 35 | K11: ='2019F'!I12 -> 96870.358 | L11: ='2021F'!I12 -> 96827.652 | N11: 35 | O11: ='2019F'!J12 -> 539.7864 | P11: ='2021F'!J12 -> 1000.9686 | R11: 35 | S11: ='2019F'!M12 -> 10.897015 | T11: ='2021F'!M12 -> 10.151578
B12: 40 | C12: ='2019F'!E13 -> 0.0016911074 | D12: ='2021F'!E13 -> 0.0023904107 | F12: 40 | G12: ='2019F'!G13 -> 0.0084199394 | H12: ='2021F'!G13 -> 0.011881052 | J12: 40 | K12: ='2019F'!I13 -> 96330.572 | L12: ='2021F'!I13 -> 95826.683 | N12: 40 | O12: ='2019F'!J13 -> 811.09758 | P12: ='2021F'!J13 -> 1138.5218 | R12: 40 | S12: ='2019F'!M13 -> 9.944016 | T12: ='2021F'!M13 -> 9.2314511
B13: 45 | C13: ='2019F'!E14 -> 0.003142511 | D13: ='2021F'!E14 -> 0.0045780039 | F13: 45 | G13: ='2019F'!G14 -> 0.015590075 | H13: ='2021F'!G14 -> 0.022631007 | J13: 45 | K13: ='2019F'!I14 -> 95519.474 | L13: ='2021F'!I14 -> 94688.161 | N13: 45 | O13: ='2019F'!J14 -> 1489.1558 | P13: ='2021F'!J14 -> 2142.8885 | R13: 45 | S13: ='2019F'!M14 -> 9.007174 | T13: ='2021F'!M14 -> 8.3123366
B14: 50 | C14: ='2019F'!E15 -> 0.0038021215 | D14: ='2021F'!E15 -> 0.0066330287 | F14: 50 | G14: ='2019F'!G15 -> 0.018831607 | H14: ='2021F'!G15 -> 0.032624151 | J14: 50 | K14: ='2019F'!I15 -> 94030.318 | L14: ='2021F'!I15 -> 92545.273 | N14: 50 | O14: ='2019F'!J15 -> 1770.742 | P14: ='2021F'!J15 -> 3019.211 | R14: 50 | S14: ='2019F'!M15 -> 8.1101748 | T14: ='2021F'!M15 -> 7.4468674
... B20: 80 | C20: ='2019F'!E21 -> 0.056122465 | D20: ='2021F'!E21 -> 0.078626706 | F20: 80 | G20: ='2019F'!G21 -> 0.24608507 | H20: ='2021F'!G21 -> 0.32855127 | J20: 80 | K20: ='2019F'!I21 -> 60837.395 | L20: ='2021F'!I21 -> 44992.11 | N20: 80 | O20: ='2019F'!J21 -> 14971.175 | P20: ='2021F'!J21 -> 14782.215 | R20: 80 | S20: ='2019F'!M21 -> 3.2540793 | T20: ='2021F'!M21 -> 3.171671
B21: 85+ | C21: ='2019F'!E22 -> 0.13011203 | D21: ='2021F'!E22 -> 0.16883111 | F21: 85+ | G21: ='2019F'!G22 -> 0.49088502 | H21: ='2021F'!G22 -> 0.59360716 | J21: 85+ | K21: ='2019F'!I22 -> 45866.22 | L21: ='2021F'!I22 -> 30209.895 | N21: 85+ | O21: ='2019F'!J22 -> 45866.22 | P21: ='2021F'!J22 -> 30209.895 | R21: 85+ | S21: ='2019F'!M22 -> 2.500109 | T21: ='2021F'!M22 -> 2.5001655

Sheet Desc.ArriH10-19
A1: Descomposición de la diferencia de la esperanza de vida al nacer de los hombres en Colima en 2010 y 2019
C3: 2010 | G3: 2019
B4: x(edad) | C4: lx | D4: nLx | E4: Tx | F4: ex | G4: lx | H4: nLx | I4: Tx | J4: ex | K4: nTriangulox | L4: %
B5: 0 | C5: 100000 | D5: 98776.989 | E5: 1734929.4 | F5: 17.349294 | G5: 100000 | H5: 99124.939 | I5: 1694223.4 | J5: 16.942234 | K5: =(C5/$C$5)*(H5/G5-D5/C5)+(I6/$C$5)*(C5/G5-C6/G6) -> 0.067039754 | L5: =K5/$K$24 -> -0.16469252
B6: 1 | C6: 98653.189 | D6: 98764.966 | E6: 1636152.4 | F6: 16.584891 | G6: 99047.868 | H6: 99152.262 | I6: 1595098.5 | J6: 16.104319 | K6: =(C6/$C$5)*(H6/G6-D6/C6)+(I7/$C$5)*(C6/G6-C7/G7) -> 0.0026352302 | L6: =K6/$K$24 -> -0.0064738109
B7: 5 | C7: 98438.196 | D7: 98630.418 | E7: 1537387.5 | F7: 15.617794 | G7: 98850.015 | H7: 98999.97 | I7: 1495946.2 | J7: 15.133495 | K7: =(C7/$C$5)*(H7/G7-D7/C7)+(I8/$C$5)*(C7/G7-C8/G8) -> 0.0036139546 | L7: =K7/$K$24 -> -0.008878184
B8: 10 | C8: 98313.382 | D8: 98454.965 | E8: 1438757.1 | F8: 14.634397 | G8: 98753.378 | H8: 98925.617 | I8: 1396946.2 | J8: 14.145807 | K8: =(C8/$C$5)*(H8/G8-D8/C8)+(I9/$C$5)*(C8/G8-C9/G9) -> -0.0023250985 | L8: =K8/$K$24 -> 0.0057119291
B9: 15 | C9: 98222.327 | D9: 98976.152 | E9: 1340302.1 | F9: 13.645595 | G9: 98641.885 | H9: 99986.857 | I9: 1298020.6 | J9: 13.15892 | K9: =(C9/$C$5)*(H9/G9-D9/C9)+(I10/$C$5)*(C9/G9-C10/G10) -> -0.041981783 | L9: =K9/$K$24 -> 0.10313411
B10: 20 | C10: 97723.11 | D10: 98838.966 | E10: 1241325.9 | F10: 12.702481 | G10: 97748.571 | H10: 100785.47 | I10: 1198033.8 | J10: 12.256279 | K10: =(C10/$C$5)*(H10/G10-D10/C10)+(I11/$C$5)*(C10/G10-C11/G11) -> -0.12753367 | L10: =K10/$K$24 -> 0.31330428
B11: 25 | C11: 96982.54 | D11: 98487.891 | E11: 1142487 | F11: 11.780337 | G11: 95727.302 | H11: 99372.099 | I11: 1097248.3 | J11: 11.462229 | K11: =(C11/$C$5)*(H11/G11-D11/C11)+(I12/$C$5)*(C11/G11-C12/G12) -> -0.13407687 | L11: =K11/$K$24 -> 0.32937855
B12: 30 | C12: 95982.306 | D12: 97817.878 | E12: 1043999.1 | F12: 10.876995 | G12: 93300.771 | H12: 96799.166 | I12: 997876.2 | J12: 10.695262 | K12: =(C12/$C$5)*(H12/G12-D12/C12)+(I13/$C$5)*(C12/G12-C13/G13) -> -0.098798078 | L12: =K12/$K$24 -> 0.24271127
B13: 35 | C13: 94761.925 | D13: 97217.364 | E13: 946181.21 | F13: 9.9848247 | G13: 90971.842 | H13: 94186.906 | I13: 901077.04 | J13: 9.9050104 | K13: =(C13/$C$5)*(H13/G13-D13/C13)+(I14/$C$5)*(C13/G13-C14/G14) -> -0.045162475 | L13: =K13/$K$24 -> 0.11094792
B14: 40 | C14: 93128.299 | D14: 96101.34 | E14: 848963.84 | F14: 9.1160673 | G14: 88831.799 | H14: 92967.667 | I14: 806890.13 | J14: 9.0833479 | K14: =(C14/$C$5)*(H14/G14-D14/C14)+(I15/$C$5)*(C14/G14-C15/G15) -> -0.061714549 | L14: =K14/$K$24 -> 0.15161041
B15: 45 | C15: 91149.605 | D15: 94778.216 | E15: 752862.5 | F15: 8.2596354 | G15: 86077.887 | H15: 90330.761 | I15: 713922.47 | J15: 8.2939125 | K15: =(C15/$C$5)*(H15/G15-D15/C15)+(I16/$C$5)*(C15/G15-C16/G16) -> -0.034926257 | L15: =K15/$K$24 -> 0.085801228
B16: 50 | C16: 88733.865 | D16: 93387.821 | E16: 658084.29 | F16: 7.4163826 | G16: 83245.971 | H16: 88287.579 | I16: 623591.7 | J16: 7.4909536 | K16: =(C16/$C$5)*(H16/G16-D16/C16)+(I17/$C$5)*(C16/G16-C17/G17) -> -0.024948921 | L16: =K16/$K$24 -> 0.061290509
... B22: 80 | C22: 43031.953 | D22: 63768.669 | E22: 136800.69 | F22: 3.1790491 | G22: 42742.465 | H22: 59875.075 | I22: 138190.22 | J22: 3.2330896 | K22: =(C22/$C$5)*(H22/G22-D22/C22)+(I23/$C$5)*(C22/G22-C23/G23) -> 0.02325807 | L22: =K22/$K$24 -> -0.057136697
B23: 85+ | C23: 29210.809 | D23: 73032.022 | E23: 73032.022 | F23: 2.5001712 | G23: 31324.058 | H23: 78315.144 | I23: 78315.144 | J23: 2.5001596 | K23: =(C23/C5)*(I23/G23-E23/C23) -> -3.3732042e-06 | L23: =K23/$K$24 -> 8.2867471e-06
K24: =SUM(K5:K23) -> -0.40706011 | M24: =J5-F5 -> -0.40706011

Sheet Desc.ArriH19-21
A1: Descomposición de la diferencia de la esperanza de vida al nacer de los hombres en Colima en 2019 y 2021
C3: 2019 | G3: 2021
B4: x(edad) | C4: lx | D4: nLx | E4: Tx | F4: ex | G4: lx | H4: nLx | I4: Tx | J4: ex | K4: nTriangulox | L4: %
B5: 0 | C5: 100000 | D5: 99124.939 | E5: 1694223.4 | F5: 16.942234 | G5: 100000 | H5: 99020.168 | I5: 1606974.1 | J5: 16.069741 | K5: =(C5/$C$5)*(H5/G5-D5/C5)+(I6/$C$5)*(C5/G5-C6/G6) -> 14.19691 | L5: =K5/$K$24 -> -16.271658
B6: 1 | C6: 99047.868 | D6: 99152.262 | E6: 1595098.5 | F6: 16.104319 | G6: =G5*F5 -> 1694223.4 | H6: 99036.162 | I6: 1507953.9 | J6: 15.242621 | K6: =(C6/$C$5)*(H6/G6-D6/C6)+(I7/$C$5)*(C6/G6-C7/G7) -> -0.16098555 | L6: =K6/$K$24 -> 0.18451211
B7: 5 | C7: 98850.015 | D7: 98999.97 | E7: 1495946.2 | F7: 15.133495 | G7: =G6*F6 -> 27284315 | H7: 98950.365 | I7: 1408917.8 | J7: 14.27067 | K7: =(C7/$C$5)*(H7/G7-D7/C7)+(I8/$C$5)*(C7/G7-C8/G8) -> -0.94208816 | L7: =K7/$K$24 -> 1.0797657
B8: 10 | C8: 98753.378 | D8: 98925.617 | E8: 1396946.2 | F8: 14.145807 | G8: =G7*F7 -> 4.1290705e+08 | H8: 98779.359 | I8: 1309967.4 | J8: 13.287904 | K8: =(C8/$C$5)*(H8/G8-D8/C8)+(I9/$C$5)*(C8/G8-C9/G9) -> -0.98632771 | L8: =K8/$K$24 -> 1.1304705
B9: 15 | C9: 98641.885 | D9: 99986.857 | E9: 1298020.6 | F9: 13.15892 | G9: =G8*F8 -> 5.8409035e+09 | H9: 99665.541 | I9: 1211188.1 | J9: 12.301798 | K9: =(C9/$C$5)*(H9/G9-D9/C9)+(I10/$C$5)*(C9/G9-C10/G10) -> -0.99967816 | L9: =K9/$K$24 -> 1.145772
B10: 20 | C10: 97748.571 | D10: 100785.47 | E10: 1198033.8 | F10: 12.256279 | G10: =G9*F9 -> 7.6859979e+10 | H10: 100666.68 | I10: 1111522.5 | J10: 11.382337 | K10: =(C10/$C$5)*(H10/G10-D10/C10)+(I11/$C$5)*(C10/G10-C11/G11) -> -1.0078416 | L10: =K10/$K$24 -> 1.1551284
B11: 25 | C11: 95727.302 | D11: 99372.099 | E11: 1097248.3 | F11: 11.462229 | G11: =G10*F10 -> 9.4201737e+11 | H11: 99517.84 | I11: 1010855.8 | J11: 10.568536 | K11: =(C11/$C$5)*(H11/G11-D11/C11)+(I12/$C$5)*(C11/G11-C12/G12) -> -0.99372004 | L11: =K11/$K$24 -> 1.1389431
B12: 30 | C12: 93300.771 | D12: 96799.166 | E12: 997876.2 | F12: 10.695262 | G12: =G11*F11 -> 1.0797619e+13 | H12: 96872.409 | I12: 911337.99 | J12: 9.7918693 | K12: =(C12/$C$5)*(H12/G12-D12/C12)+(I13/$C$5)*(C12/G12-C13/G13) -> -0.96799159 | L12: =K12/$K$24 -> 1.1094547
B13: 35 | C13: 90971.842 | D13: 94186.906 | E13: 901077.04 | F13: 9.9050104 | G13: =G12*F12 -> 1.1548337e+14 | H13: 95166.47 | I13: 814465.58 | J13: 8.9956559 | K13: =(C13/$C$5)*(H13/G13-D13/C13)+(I14/$C$5)*(C13/G13-C14/G14) -> -0.94186905 | L13: =K13/$K$24 -> 1.0795146
B14: 40 | C14: 88831.799 | D14: 92967.667 | E14: 806890.13 | F14: 9.0833479 | G14: =G13*F13 -> 1.143864e+15 | H14: 92515.025 | I14: 719299.11 | J14: 8.2244323 | K14: =(C14/$C$5)*(H14/G14-D14/C14)+(I15/$C$5)*(C14/G14-C15/G15) -> -0.92967667 | L14: =K14/$K$24 -> 1.0655404
B15: 45 | C15: 86077.887 | D15: 90330.761 | E15: 713922.47 | F15: 8.2939125 | G15: =G14*F14 -> 1.0390114e+16 | H15: 89368.621 | I15: 626784.09 | J15: 7.4536101 | K15: =(C15/$C$5)*(H15/G15-D15/C15)+(I16/$C$5)*(C15/G15-C16/G16) -> -0.90330761 | L15: =K15/$K$24 -> 1.0353177
